Workbook

Sheet 여고부개인통합
B1: 2026 한국중고배구연맹 여고부 개인 선수별 데이터
C2: 2026년 3월 춘계 (단양) + 4월 연맹 (삼척) | AL2: 개인별 평가 지수
B3: No | D3: Team | E3: Name | F3: Grade 학년 | G3: Position 1 포지션1 | H3: Position 2 포지션2 | I3: Height (cm) | J3: Weight (kg) | K3: # Jersey 등번호 | L3: Match Played 경기 수 | M3: Set Played 경기 Set수 | N3: Kills ① 공격 성공 | O3: Kills Assist ② 어시스트 | P3: Attack ③ 공 격 | Q3: Attack Errors 공격실패 ④ | R3: Total Attack ①+③+④ 공격 합계 | S3: Hit % (①-④) / TA 공격 효율 | T3: Blocks ⑤ 블로킹 성공 | U3: Block Errors 블로킹 실패 ⑥ | V3: Block Assist 블로킹 도움 ⑦ | W3: Serve ⑧ 서 브 | X3: Serve Aces 서브 에이스 ⑨ | Y3: Serve Errors 서브 실패 ⑩ | Z3: Total Serve ⑧+⑨+⑩ 서브 합계 | AA3: Ball Handling Errors ⑪ 볼처리 실패 | AB3: Total Points ①+⑤+⑨ 득점 합계 | AC3: Player Score ①+⑤+⑨+⑦x75% 공격 지수 | AD3: Receive Att. 리시브 합계 ⑫+⑬ | AE3: Receive Successes ⑫ 리시브 성공 | AF3: Receive Failures ⑬ 리시브 실패 | AG3: Rcv Suc Rate (%) | AH3: Digs ⑭ 디그 | AI3: Digs / Set 디그수/세트 | AL3: Kills / Set 공격득점 | AM3: Total Attack / Set 공격횟수/세트 | AN3: Hit % 공격성공율 | AO3: Blocks / Set 블로킹득점/세트 | AP3: Serve Aces / Set | AQ3: Total Points / Set | AR3: Player Score / Set 공격지수 | AS3: 리시브 실패 /세트 | AT3: Dig / Set
B4: 1 | C4: =if(D4=D3,C3+1,1) -> 1 | D4: 선명여고 | E4: 곽도연 | F4: 3 | G4: MB | H4: - | I4: 182 | J4: 65 | K4: 1 | L4: =SUMIFS('3월 단양 개인별 STAT'!L:L, '3월 단양 개인별 STAT'!$D:$D, $D4, '3월 단양 개인별 STAT'!$E:$E, $E4) + SUMIFS('4월 삼척 개인별 STAT'!L:L, '4월 삼척 개인별 STAT'!$D:$D, $D4, '4월 삼척 개인별 STAT'!$E:$E, $E4) -> 2 | M4: =SUMIFS('3월 단양 개인별 STAT'!M:M, '3월 단양 개인별 STAT'!$D:$D, $D4, '3월 단양 개인별 STAT'!$E:$E, $E4) + SUMIFS('4월 삼척 개인별 STAT'!M:M, '4월 삼척 개인별 STAT'!$D:$D, $D4, '4월 삼척 개인별 STAT'!$E:$E, $E4) -> 7 | N4: =SUMIFS('3월 단양 개인별 STAT'!N:N, '3월 단양 개인별 STAT'!$D:$D, $D4, '3월 단양 개인별 STAT'!$E:$E, $E4) + SUMIFS('4월 삼척 개인별 STAT'!N:N, '4월 삼척 개인별 STAT'!$D:$D, $D4, '4월 삼척 개인별 STAT'!$E:$E, $E4) -> 5 | O4: =SUMIFS('3월 단양 개인별 STAT'!O:O, '3월 단양 개인별 STAT'!$D:$D, $D4, '3월 단양 개인별 STAT'!$E:$E, $E4) + SUMIFS('4월 삼척 개인별 STAT'!O:O, '4월 삼척 개인별 STAT'!$D:$D, $D4, '4월 삼척 개인별 STAT'!$E:$E, $E4) -> 0 | P4: =SUMIFS('3월 단양 개인별 STAT'!P:P, '3월 단양 개인별 STAT'!$D:$D, $D4, '3월 단양 개인별 STAT'!$E:$E, $E4) + SUMIFS('4월 삼척 개인별 STAT'!P:P, '4월 삼척 개인별 STAT'!$D:$D, $D4, '4월 삼척 개인별 STAT'!$E:$E, $E4) -> 5 | Q4: =SUMIFS('3월 단양 개인별 STAT'!Q:Q, '3월 단양 개인별 STAT'!$D:$D, $D4, '3월 단양 개인별 STAT'!$E:$E, $E4) + SUMIFS('4월 삼척 개인별 STAT'!Q:Q, '4월 삼척 개인별 STAT'!$D:$D, $D4, '4월 삼척 개인별 STAT'!$E:$E, $E4) -> 4 | R4: =if(Q4+P4+N4=0,"-",Q4+P4+N4) -> 14 | S4: =if(iferror((N4-Q4)/R4,0)=0,"-",round((N4-Q4)/R4,2)) -> 0.07 | T4: =SUMIFS('3월 단양 개인별 STAT'!T:T, '3월 단양 개인별 STAT'!$D:$D, $D4, '3월 단양 개인별 STAT'!$E:$E, $E4) + SUMIFS('4월 삼척 개인별 STAT'!T:T, '4월 삼척 개인별 STAT'!$D:$D, $D4, '4월 삼척 개인별 STAT'!$E:$E, $E4) -> 3 | U4: =SUMIFS('3월 단양 개인별 STAT'!U:U, '3월 단양 개인별 STAT'!$D:$D, $D4, '3월 단양 개인별 STAT'!$E:$E, $E4) + SUMIFS('4월 삼척 개인별 STAT'!U:U, '4월 삼척 개인별 STAT'!$D:$D, $D4, '4월 삼척 개인별 STAT'!$E:$E, $E4) -> 0 | V4: =SUMIFS('3월 단양 개인별 STAT'!V:V, '3월 단양 개인별 STAT'!$D:$D, $D4, '3월 단양 개인별 STAT'!$E:$E, $E4) + SUMIFS('4월 삼척 개인별 STAT'!V:V, '4월 삼척 개인별 STAT'!$D:$D, $D4, '4월 삼척 개인별 STAT'!$E:$E, $E4) -> 0 | W4: =SUMIFS('3월 단양 개인별 STAT'!W:W, '3월 단양 개인별 STAT'!$D:$D, $D4, '3월 단양 개인별 STAT'!$E:$E, $E4) + SUMIFS('4월 삼척 개인별 STAT'!W:W, '4월 삼척 개인별 STAT'!$D:$D, $D4, '4월 삼척 개인별 STAT'!$E:$E, $E4) -> 30 | X4: =SUMIFS('3월 단양 개인별 STAT'!X:X, '3월 단양 개인별 STAT'!$D:$D, $D4, '3월 단양 개인별 STAT'!$E:$E, $E4) + SUMIFS('4월 삼척 개인별 STAT'!X:X, '4월 삼척 개인별 STAT'!$D:$D, $D4, '4월 삼척 개인별 STAT'!$E:$E, $E4) -> 1 | Y4: =SUMIFS('3월 단양 개인별 STAT'!Y:Y, '3월 단양 개인별 STAT'!$D:$D, $D4, '3월 단양 개인별 STAT'!$E:$E, $E4) + SUMIFS('4월 삼척 개인별 STAT'!Y:Y, '4월 삼척 개인별 STAT'!$D:$D, $D4, '4월 삼척 개인별 STAT'!$E:$E, $E4) -> 0 | Z4: =IF(Y4+X4+W4=0,"-",Y4+X4+W4) -> 31 | AA4: =SUMIFS('3월 단양 개인별 STAT'!AA:AA, '3월 단양 개인별 STAT'!$D:$D, $D4, '3월 단양 개인별 STAT'!$E:$E, $E4) + SUMIFS('4월 삼척 개인별 STAT'!AA:AA, '4월 삼척 개인별 STAT'!$D:$D, $D4, '4월 삼척 개인별 STAT'!$E:$E, $E4) -> 0 | AB4: =if((T4+X4+N4)=0, "-",T4+X4+N4) -> 9 | AC4: =N4+T4+X4+(V4*0.75) -> 9 | AD4: =IF(AE4+AF4=0,"-",AE4+AF4) -> 2 | AE4: =SUMIFS('3월 단양 개인별 STAT'!AE:AE, '3월 단양 개인별 STAT'!$D:$D, $D4, '3월 단양 개인별 STAT'!$E:$E, $E4) + SUMIFS('4월 삼척 개인별 STAT'!AE:AE, '4월 삼척 개인별 STAT'!$D:$D, $D4, '4월 삼척 개인별 STAT'!$E:$E, $E4) -> 2 | AF4: =SUMIFS('3월 단양 개인별 STAT'!AF:AF, '3월 단양 개인별 STAT'!$D:$D, $D4, '3월 단양 개인별 STAT'!$E:$E, $E4) + SUMIFS('4월 삼척 개인별 STAT'!AF:AF, '4월 삼척 개인별 STAT'!$D:$D, $D4, '4월 삼척 개인별 STAT'!$E:$E, $E4) -> 0 | AG4: =iferror((AE4/AD4)*100,"-") -> 100 | AH4: =SUMIFS('3월 단양 개인별 STAT'!AH:AH, '3월 단양 개인별 STAT'!$D:$D, $D4, '3월 단양 개인별 STAT'!$E:$E, $E4) + SUMIFS('4월 삼척 개인별 STAT'!AH:AH, '4월 삼척 개인별 STAT'!$D:$D, $D4, '4월 삼척 개인별 STAT'!$E:$E, $E4) -> 3 | AI4: =IFERROR(IF(MOD(AH4/M4, 1)=0, TEXT(AH4/M4, "0"), TEXT(AH4/M4, "0.00")), "-") -> 0.43 | AL4: =iferror(N4/$M4,"-") -> 0.71428571 | AM4: =iferror(R4/$M4,"-") -> 2 | AN4: =iferror(N4/R4,"-") -> 0.35714286 | AO4: =iferror(T4/$M4,"-") -> 0.42857143 | AP4: =iferror(X4/$M4,"-") -> 0.14285714 | AQ4: =iferror(AB4/$M4,"-") -> 1.2857143 | AR4: =iferror(AC4/$M4,"-") -> 1.2857143 | AS4: =iferror(AF4/M4,"-") -> 0 | AT4: =AI4 -> 0.43
B5: 2 | C5: =if(D5=D4,C4+1,1) -> 2 | D5: 선명여고 | E5: 나민지 | F5: 3 | G5: Li | H5: - | I5: 161 | J5: 59 | K5: 3 | L5: =SUMIFS('3월 단양 개인별 STAT'!L:L, '3월 단양 개인별 STAT'!$D:$D, $D5, '3월 단양 개인별 STAT'!$E:$E, $E5) + SUMIFS('4월 삼척 개인별 STAT'!L:L, '4월 삼척 개인별 STAT'!$D:$D, $D5, '4월 삼척 개인별 STAT'!$E:$E, $E5) -> 2 | M5: =SUMIFS('3월 단양 개인별 STAT'!M:M, '3월 단양 개인별 STAT'!$D:$D, $D5, '3월 단양 개인별 STAT'!$E:$E, $E5) + SUMIFS('4월 삼척 개인별 STAT'!M:M, '4월 삼척 개인별 STAT'!$D:$D, $D5, '4월 삼척 개인별 STAT'!$E:$E, $E5) -> 7 | N5: =SUMIFS('3월 단양 개인별 STAT'!N:N, '3월 단양 개인별 STAT'!$D:$D, $D5, '3월 단양 개인별 STAT'!$E:$E, $E5) + SUMIFS('4월 삼척 개인별 STAT'!N:N, '4월 삼척 개인별 STAT'!$D:$D, $D5, '4월 삼척 개인별 STAT'!$E:$E, $E5) -> 0 | O5: =SUMIFS('3월 단양 개인별 STAT'!O:O, '3월 단양 개인별 STAT'!$D:$D, $D5, '3월 단양 개인별 STAT'!$E:$E, $E5) + SUMIFS('4월 삼척 개인별 STAT'!O:O, '4월 삼척 개인별 STAT'!$D:$D, $D5, '4월 삼척 개인별 STAT'!$E:$E, $E5) -> 4 | P5: =SUMIFS('3월 단양 개인별 STAT'!P:P, '3월 단양 개인별 STAT'!$D:$D, $D5, '3월 단양 개인별 STAT'!$E:$E, $E5) + SUMIFS('4월 삼척 개인별 STAT'!P:P, '4월 삼척 개인별 STAT'!$D:$D, $D5, '4월 삼척 개인별 STAT'!$E:$E, $E5) -> 0 | Q5: =SUMIFS('3월 단양 개인별 STAT'!Q:Q, '3월 단양 개인별 STAT'!$D:$D, $D5, '3월 단양 개인별 STAT'!$E:$E, $E5) + SUMIFS('4월 삼척 개인별 STAT'!Q:Q, '4월 삼척 개인별 STAT'!$D:$D, $D5, '4월 삼척 개인별 STAT'!$E:$E, $E5) -> 0 | R5: =if(Q5+P5+N5=0,"-",Q5+P5+N5) -> - | S5: =if(iferror((N5-Q5)/R5,0)=0,"-",round((N5-Q5)/R5,2)) -> - | T5: =SUMIFS('3월 단양 개인별 STAT'!T:T, '3월 단양 개인별 STAT'!$D:$D, $D5, '3월 단양 개인별 STAT'!$E:$E, $E5) + SUMIFS('4월 삼척 개인별 STAT'!T:T, '4월 삼척 개인별 STAT'!$D:$D, $D5, '4월 삼척 개인별 STAT'!$E:$E, $E5) -> 0 | U5: =SUMIFS('3월 단양 개인별 STAT'!U:U, '3월 단양 개인별 STAT'!$D:$D, $D5, '3월 단양 개인별 STAT'!$E:$E, $E5) + SUMIFS('4월 삼척 개인별 STAT'!U:U, '4월 삼척 개인별 STAT'!$D:$D, $D5, '4월 삼척 개인별 STAT'!$E:$E, $E5) -> 0 | V5: =SUMIFS('3월 단양 개인별 STAT'!V:V, '3월 단양 개인별 STAT'!$D:$D, $D5, '3월 단양 개인별 STAT'!$E:$E, $E5) + SUMIFS('4월 삼척 개인별 STAT'!V:V, '4월 삼척 개인별 STAT'!$D:$D, $D5, '4월 삼척 개인별 STAT'!$E:$E, $E5) -> 0 | W5: =SUMIFS('3월 단양 개인별 STAT'!W:W, '3월 단양 개인별 STAT'!$D:$D, $D5, '3월 단양 개인별 STAT'!$E:$E, $E5) + SUMIFS('4월 삼척 개인별 STAT'!W:W, '4월 삼척 개인별 STAT'!$D:$D, $D5, '4월 삼척 개인별 STAT'!$E:$E, $E5) -> 0 | X5: =SUMIFS('3월 단양 개인별 STAT'!X:X, '3월 단양 개인별 STAT'!$D:$D, $D5, '3월 단양 개인별 STAT'!$E:$E, $E5) + SUMIFS('4월 삼척 개인별 STAT'!X:X, '4월 삼척 개인별 STAT'!$D:$D, $D5, '4월 삼척 개인별 STAT'!$E:$E, $E5) -> 0 | Y5: =SUMIFS('3월 단양 개인별 STAT'!Y:Y, '3월 단양 개인별 STAT'!$D:$D, $D5, '3월 단양 개인별 STAT'!$E:$E, $E5) + SUMIFS('4월 삼척 개인별 STAT'!Y:Y, '4월 삼척 개인별 STAT'!$D:$D, $D5, '4월 삼척 개인별 STAT'!$E:$E, $E5) -> 0 | Z5: =IF(Y5+X5+W5=0,"-",Y5+X5+W5) -> - | AA5: =SUMIFS('3월 단양 개인별 STAT'!AA:AA, '3월 단양 개인별 STAT'!$D:$D, $D5, '3월 단양 개인별 STAT'!$E:$E, $E5) + SUMIFS('4월 삼척 개인별 STAT'!AA:AA, '4월 삼척 개인별 STAT'!$D:$D, $D5, '4월 삼척 개인별 STAT'!$E:$E, $E5) -> 0 | AB5: =if((T5+X5+N5)=0, "-",T5+X5+N5) -> - | AC5: =N5+T5+X5+(V5*0.75) -> 0 | AD5: =IF(AE5+AF5=0,"-",AE5+AF5) -> 42 | AE5: =SUMIFS('3월 단양 개인별 STAT'!AE:AE, '3월 단양 개인별 STAT'!$D:$D, $D5, '3월 단양 개인별 STAT'!$E:$E, $E5) + SUMIFS('4월 삼척 개인별 STAT'!AE:AE, '4월 삼척 개인별 STAT'!$D:$D, $D5, '4월 삼척 개인별 STAT'!$E:$E, $E5) -> 39 | AF5: =SUMIFS('3월 단양 개인별 STAT'!AF:AF, '3월 단양 개인별 STAT'!$D:$D, $D5, '3월 단양 개인별 STAT'!$E:$E, $E5) + SUMIFS('4월 삼척 개인별 STAT'!AF:AF, '4월 삼척 개인별 STAT'!$D:$D, $D5, '4월 삼척 개인별 STAT'!$E:$E, $E5) -> 3 | AG5: =iferror((AE5/AD5)*100,"-") -> 92.857143 | AH5: =SUMIFS('3월 단양 개인별 STAT'!AH:AH, '3월 단양 개인별 STAT'!$D:$D, $D5, '3월 단양 개인별 STAT'!$E:$E, $E5) + SUMIFS('4월 삼척 개인별 STAT'!AH:AH, '4월 삼척 개인별 STAT'!$D:$D, $D5, '4월 삼척 개인별 STAT'!$E:$E, $E5) -> 18 | AI5: =IFERROR(IF(MOD(AH5/M5, 1)=0, TEXT(AH5/M5, "0"), TEXT(AH5/M5, "0.00")), "-") -> 2.57 | AL5: =iferror(N5/$M5,"-") -> 0 | AM5: =iferror(R5/$M5,"-") -> - | AN5: =iferror(N5/R5,"-") -> - | AO5: =iferror(T5/$M5,"-") -> 0 | AP5: =iferror(X5/$M5,"-") -> 0 | AQ5: =iferror(AB5/$M5,"-") -> - | AR5: =iferror(AC5/$M5,"-") -> 0 | AS5: =iferror(AF5/M5,"-") -> 0.42857143 | AT5: =AI5 -> 2.57
B6: 3 | C6: =if(D6=D5,C5+1,1) -> 3 | D6: 선명여고 | E6: 오해솔 | F6: 3 | G6: OH | H6: - | I6: 183 | J6: 66 | K6: 5 | L6: =SUMIFS('3월 단양 개인별 STAT'!L:L, '3월 단양 개인별 STAT'!$D:$D, $D6, '3월 단양 개인별 STAT'!$E:$E, $E6) + SUMIFS('4월 삼척 개인별 STAT'!L:L, '4월 삼척 개인별 STAT'!$D:$D, $D6, '4월 삼척 개인별 STAT'!$E:$E, $E6) -> 1 | M6: =SUMIFS('3월 단양 개인별 STAT'!M:M, '3월 단양 개인별 STAT'!$D:$D, $D6, '3월 단양 개인별 STAT'!$E:$E, $E6) + SUMIFS('4월 삼척 개인별 STAT'!M:M, '4월 삼척 개인별 STAT'!$D:$D, $D6, '4월 삼척 개인별 STAT'!$E:$E, $E6) -> 1 | N6: =SUMIFS('3월 단양 개인별 STAT'!N:N, '3월 단양 개인별 STAT'!$D:$D, $D6, '3월 단양 개인별 STAT'!$E:$E, $E6) + SUMIFS('4월 삼척 개인별 STAT'!N:N, '4월 삼척 개인별 STAT'!$D:$D, $D6, '4월 삼척 개인별 STAT'!$E:$E, $E6) -> 0 | O6: =SUMIFS('3월 단양 개인별 STAT'!O:O, '3월 단양 개인별 STAT'!$D:$D, $D6, '3월 단양 개인별 STAT'!$E:$E, $E6) + SUMIFS('4월 삼척 개인별 STAT'!O:O, '4월 삼척 개인별 STAT'!$D:$D, $D6, '4월 삼척 개인별 STAT'!$E:$E, $E6) -> 0 | P6: =SUMIFS('3월 단양 개인별 STAT'!P:P, '3월 단양 개인별 STAT'!$D:$D, $D6, '3월 단양 개인별 STAT'!$E:$E, $E6) + SUMIFS('4월 삼척 개인별 STAT'!P:P, '4월 삼척 개인별 STAT'!$D:$D, $D6, '4월 삼척 개인별 STAT'!$E:$E, $E6) -> 0 | Q6: =SUMIFS('3월 단양 개인별 STAT'!Q:Q, '3월 단양 개인별 STAT'!$D:$D, $D6, '3월 단양 개인별 STAT'!$E:$E, $E6) + SUMIFS('4월 삼척 개인별 STAT'!Q:Q, '4월 삼척 개인별 STAT'!$D:$D, $D6, '4월 삼척 개인별 STAT'!$E:$E, $E6) -> 0 | R6: =if(Q6+P6+N6=0,"-",Q6+P6+N6) -> - | S6: =if(iferror((N6-Q6)/R6,0)=0,"-",round((N6-Q6)/R6,2)) -> - | T6: =SUMIFS('3월 단양 개인별 STAT'!T:T, '3월 단양 개인별 STAT'!$D:$D, $D6, '3월 단양 개인별 STAT'!$E:$E, $E6) + SUMIFS('4월 삼척 개인별 STAT'!T:T, '4월 삼척 개인별 STAT'!$D:$D, $D6, '4월 삼척 개인별 STAT'!$E:$E, $E6) -> 0 | U6: =SUMIFS('3월 단양 개인별 STAT'!U:U, '3월 단양 개인별 STAT'!$D:$D, $D6, '3월 단양 개인별 STAT'!$E:$E, $E6) + SUMIFS('4월 삼척 개인별 STAT'!U:U, '4월 삼척 개인별 STAT'!$D:$D, $D6, '4월 삼척 개인별 STAT'!$E:$E, $E6) -> 0 | V6: =SUMIFS('3월 단양 개인별 STAT'!V:V, '3월 단양 개인별 STAT'!$D:$D, $D6, '3월 단양 개인별 STAT'!$E:$E, $E6) + SUMIFS('4월 삼척 개인별 STAT'!V:V, '4월 삼척 개인별 STAT'!$D:$D, $D6, '4월 삼척 개인별 STAT'!$E:$E, $E6) -> 0 | W6: =SUMIFS('3월 단양 개인별 STAT'!W:W, '3월 단양 개인별 STAT'!$D:$D, $D6, '3월 단양 개인별 STAT'!$E:$E, $E6) + SUMIFS('4월 삼척 개인별 STAT'!W:W, '4월 삼척 개인별 STAT'!$D:$D, $D6, '4월 삼척 개인별 STAT'!$E:$E, $E6) -> 2 | X6: =SUMIFS('3월 단양 개인별 STAT'!X:X, '3월 단양 개인별 STAT'!$D:$D, $D6, '3월 단양 개인별 STAT'!$E:$E, $E6) + SUMIFS('4월 삼척 개인별 STAT'!X:X, '4월 삼척 개인별 STAT'!$D:$D, $D6, '4월 삼척 개인별 STAT'!$E:$E, $E6) -> 0 | Y6: =SUMIFS('3월 단양 개인별 STAT'!Y:Y, '3월 단양 개인별 STAT'!$D:$D, $D6, '3월 단양 개인별 STAT'!$E:$E, $E6) + SUMIFS('4월 삼척 개인별 STAT'!Y:Y, '4월 삼척 개인별 STAT'!$D:$D, $D6, '4월 삼척 개인별 STAT'!$E:$E, $E6) -> 0 | Z6: =IF(Y6+X6+W6=0,"-",Y6+X6+W6) -> 2 | AA6: =SUMIFS('3월 단양 개인별 STAT'!AA:AA, '3월 단양 개인별 STAT'!$D:$D, $D6, '3월 단양 개인별 STAT'!$E:$E, $E6) + SUMIFS('4월 삼척 개인별 STAT'!AA:AA, '4월 삼척 개인별 STAT'!$D:$D, $D6, '4월 삼척 개인별 STAT'!$E:$E, $E6) -> 0 | AB6: =if((T6+X6+N6)=0, "-",T6+X6+N6) -> - | AC6: =N6+T6+X6+(V6*0.75) -> 0 | AD6: =IF(AE6+AF6=0,"-",AE6+AF6) -> 2 | AE6: =SUMIFS('3월 단양 개인별 STAT'!AE:AE, '3월 단양 개인별 STAT'!$D:$D, $D6, '3월 단양 개인별 STAT'!$E:$E, $E6) + SUMIFS('4월 삼척 개인별 STAT'!AE:AE, '4월 삼척 개인별 STAT'!$D:$D, $D6, '4월 삼척 개인별 STAT'!$E:$E, $E6) -> 2 | AF6: =SUMIFS('3월 단양 개인별 STAT'!AF:AF, '3월 단양 개인별 STAT'!$D:$D, $D6, '3월 단양 개인별 STAT'!$E:$E, $E6) + SUMIFS('4월 삼척 개인별 STAT'!AF:AF, '4월 삼척 개인별 STAT'!$D:$D, $D6, '4월 삼척 개인별 STAT'!$E:$E, $E6) -> 0 | AG6: =iferror((AE6/AD6)*100,"-") -> 100 | AH6: =SUMIFS('3월 단양 개인별 STAT'!AH:AH, '3월 단양 개인별 STAT'!$D:$D, $D6, '3월 단양 개인별 STAT'!$E:$E, $E6) + SUMIFS('4월 삼척 개인별 STAT'!AH:AH, '4월 삼척 개인별 STAT'!$D:$D, $D6, '4월 삼척 개인별 STAT'!$E:$E, $E6) -> 0 | AI6: =IFERROR(IF(MOD(AH6/M6, 1)=0, TEXT(AH6/M6, "0"), TEXT(AH6/M6, "0.00")), "-") -> 0 | AL6: =iferror(N6/$M6,"-") -> 0 | AM6: =iferror(R6/$M6,"-") -> - | AN6: =iferror(N6/R6,"-") -> - | AO6: =iferror(T6/$M6,"-") -> 0 | AP6: =iferror(X6/$M6,"-") -> 0 | AQ6: =iferror(AB6/$M6,"-") -> - | AR6: =iferror(AC6/$M6,"-") -> 0 | AS6: =iferror(AF6/M6,"-") -> 0 | AT6: =AI6 -> 0
B7: 4 | C7: =if(D7=D6,C6+1,1) -> 4 | D7: 선명여고 | E7: 최윤겸 | F7: 2 | G7: S | H7: - | I7: 167 | J7: 60 | K7: 7 | L7: =SUMIFS('3월 단양 개인별 STAT'!L:L, '3월 단양 개인별 STAT'!$D:$D, $D7, '3월 단양 개인별 STAT'!$E:$E, $E7) + SUMIFS('4월 삼척 개인별 STAT'!L:L, '4월 삼척 개인별 STAT'!$D:$D, $D7, '4월 삼척 개인별 STAT'!$E:$E, $E7) -> 2 | M7: =SUMIFS('3월 단양 개인별 STAT'!M:M, '3월 단양 개인별 STAT'!$D:$D, $D7, '3월 단양 개인별 STAT'!$E:$E, $E7) + SUMIFS('4월 삼척 개인별 STAT'!M:M, '4월 삼척 개인별 STAT'!$D:$D, $D7, '4월 삼척 개인별 STAT'!$E:$E, $E7) -> 7 | N7: =SUMIFS('3월 단양 개인별 STAT'!N:N, '3월 단양 개인별 STAT'!$D:$D, $D7, '3월 단양 개인별 STAT'!$E:$E, $E7) + SUMIFS('4월 삼척 개인별 STAT'!N:N, '4월 삼척 개인별 STAT'!$D:$D, $D7, '4월 삼척 개인별 STAT'!$E:$E, $E7) -> 0 | O7: =SUMIFS('3월 단양 개인별 STAT'!O:O, '3월 단양 개인별 STAT'!$D:$D, $D7, '3월 단양 개인별 STAT'!$E:$E, $E7) + SUMIFS('4월 삼척 개인별 STAT'!O:O, '4월 삼척 개인별 STAT'!$D:$D, $D7, '4월 삼척 개인별 STAT'!$E:$E, $E7) -> 1 | P7: =SUMIFS('3월 단양 개인별 STAT'!P:P, '3월 단양 개인별 STAT'!$D:$D, $D7, '3월 단양 개인별 STAT'!$E:$E, $E7) + SUMIFS('4월 삼척 개인별 STAT'!P:P, '4월 삼척 개인별 STAT'!$D:$D, $D7, '4월 삼척 개인별 STAT'!$E:$E, $E7) -> 0 | Q7: =SUMIFS('3월 단양 개인별 STAT'!Q:Q, '3월 단양 개인별 STAT'!$D:$D, $D7, '3월 단양 개인별 STAT'!$E:$E, $E7) + SUMIFS('4월 삼척 개인별 STAT'!Q:Q, '4월 삼척 개인별 STAT'!$D:$D, $D7, '4월 삼척 개인별 STAT'!$E:$E, $E7) -> 0 | R7: =if(Q7+P7+N7=0,"-",Q7+P7+N7) -> - | S7: =if(iferror((N7-Q7)/R7,0)=0,"-",round((N7-Q7)/R7,2)) -> - | T7: =SUMIFS('3월 단양 개인별 STAT'!T:T, '3월 단양 개인별 STAT'!$D:$D, $D7, '3월 단양 개인별 STAT'!$E:$E, $E7) + SUMIFS('4월 삼척 개인별 STAT'!T:T, '4월 삼척 개인별 STAT'!$D:$D, $D7, '4월 삼척 개인별 STAT'!$E:$E, $E7) -> 0 | U7: =SUMIFS('3월 단양 개인별 STAT'!U:U, '3월 단양 개인별 STAT'!$D:$D, $D7, '3월 단양 개인별 STAT'!$E:$E, $E7) + SUMIFS('4월 삼척 개인별 STAT'!U:U, '4월 삼척 개인별 STAT'!$D:$D, $D7, '4월 삼척 개인별 STAT'!$E:$E, $E7) -> 0 | V7: =SUMIFS('3월 단양 개인별 STAT'!V:V, '3월 단양 개인별 STAT'!$D:$D, $D7, '3월 단양 개인별 STAT'!$E:$E, $E7) + SUMIFS('4월 삼척 개인별 STAT'!V:V, '4월 삼척 개인별 STAT'!$D:$D, $D7, '4월 삼척 개인별 STAT'!$E:$E, $E7) -> 0 | W7: =SUMIFS('3월 단양 개인별 STAT'!W:W, '3월 단양 개인별 STAT'!$D:$D, $D7, '3월 단양 개인별 STAT'!$E:$E, $E7) + SUMIFS('4월 삼척 개인별 STAT'!W:W, '4월 삼척 개인별 STAT'!$D:$D, $D7, '4월 삼척 개인별 STAT'!$E:$E, $E7) -> 4 | X7: =SUMIFS('3월 단양 개인별 STAT'!X:X, '3월 단양 개인별 STAT'!$D:$D, $D7, '3월 단양 개인별 STAT'!$E:$E, $E7) + SUMIFS('4월 삼척 개인별 STAT'!X:X, '4월 삼척 개인별 STAT'!$D:$D, $D7, '4월 삼척 개인별 STAT'!$E:$E, $E7) -> 2 | Y7: =SUMIFS('3월 단양 개인별 STAT'!Y:Y, '3월 단양 개인별 STAT'!$D:$D, $D7, '3월 단양 개인별 STAT'!$E:$E, $E7) + SUMIFS('4월 삼척 개인별 STAT'!Y:Y, '4월 삼척 개인별 STAT'!$D:$D, $D7, '4월 삼척 개인별 STAT'!$E:$E, $E7) -> 3 | Z7: =IF(Y7+X7+W7=0,"-",Y7+X7+W7) -> 9 | AA7: =SUMIFS('3월 단양 개인별 STAT'!AA:AA, '3월 단양 개인별 STAT'!$D:$D, $D7, '3월 단양 개인별 STAT'!$E:$E, $E7) + SUMIFS('4월 삼척 개인별 STAT'!AA:AA, '4월 삼척 개인별 STAT'!$D:$D, $D7, '4월 삼척 개인별 STAT'!$E:$E, $E7) -> 0 | AB7: =if((T7+X7+N7)=0, "-",T7+X7+N7) -> 2 | AC7: =N7+T7+X7+(V7*0.75) -> 2 | AD7: =IF(AE7+AF7=0,"-",AE7+AF7) -> 1 | AE7: =SUMIFS('3월 단양 개인별 STAT'!AE:AE, '3월 단양 개인별 STAT'!$D:$D, $D7, '3월 단양 개인별 STAT'!$E:$E, $E7) + SUMIFS('4월 삼척 개인별 STAT'!AE:AE, '4월 삼척 개인별 STAT'!$D:$D, $D7, '4월 삼척 개인별 STAT'!$E:$E, $E7) -> 1 | AF7: =SUMIFS('3월 단양 개인별 STAT'!AF:AF, '3월 단양 개인별 STAT'!$D:$D, $D7, '3월 단양 개인별 STAT'!$E:$E, $E7) + SUMIFS('4월 삼척 개인별 STAT'!AF:AF, '4월 삼척 개인별 STAT'!$D:$D, $D7, '4월 삼척 개인별 STAT'!$E:$E, $E7) -> 0 | AG7: =iferror((AE7/AD7)*100,"-") -> 100 | AH7: =SUMIFS('3월 단양 개인별 STAT'!AH:AH, '3월 단양 개인별 STAT'!$D:$D, $D7, '3월 단양 개인별 STAT'!$E:$E, $E7) + SUMIFS('4월 삼척 개인별 STAT'!AH:AH, '4월 삼척 개인별 STAT'!$D:$D, $D7, '4월 삼척 개인별 STAT'!$E:$E, $E7) -> 0 | AI7: =IFERROR(IF(MOD(AH7/M7, 1)=0, TEXT(AH7/M7, "0"), TEXT(AH7/M7, "0.00")), "-") -> 0 | AL7: =iferror(N7/$M7,"-") -> 0 | AM7: =iferror(R7/$M7,"-") -> - | AN7: =iferror(N7/R7,"-") -> - | AO7: =iferror(T7/$M7,"-") -> 0 | AP7: =iferror(X7/$M7,"-") -> 0.28571429 | AQ7: =iferror(AB7/$M7,"-") -> 0.28571429 | AR7: =iferror(AC7/$M7,"-") -> 0.28571429 | AS7: =iferror(AF7/M7,"-") -> 0 | AT7: =AI7 -> 0
B8: 5 | C8: =if(D8=D7,C7+1,1) -> 5 | D8: 선명여고 | E8: 김예은 | F8: 2 | G8: OH | H8: - | I8: 168 | J8: 64 | K8: 8 | L8: =SUMIFS('3월 단양 개인별 STAT'!L:L, '3월 단양 개인별 STAT'!$D:$D, $D8, '3월 단양 개인별 STAT'!$E:$E, $E8) + SUMIFS('4월 삼척 개인별 STAT'!L:L, '4월 삼척 개인별 STAT'!$D:$D, $D8, '4월 삼척 개인별 STAT'!$E:$E, $E8) -> 2 | M8: =SUMIFS('3월 단양 개인별 STAT'!M:M, '3월 단양 개인별 STAT'!$D:$D, $D8, '3월 단양 개인별 STAT'!$E:$E, $E8) + SUMIFS('4월 삼척 개인별 STAT'!M:M, '4월 삼척 개인별 STAT'!$D:$D, $D8, '4월 삼척 개인별 STAT'!$E:$E, $E8) -> 6 | N8: =SUMIFS('3월 단양 개인별 STAT'!N:N, '3월 단양 개인별 STAT'!$D:$D, $D8, '3월 단양 개인별 STAT'!$E:$E, $E8) + SUMIFS('4월 삼척 개인별 STAT'!N:N, '4월 삼척 개인별 STAT'!$D:$D, $D8, '4월 삼척 개인별 STAT'!$E:$E, $E8) -> 0 | O8: =SUMIFS('3월 단양 개인별 STAT'!O:O, '3월 단양 개인별 STAT'!$D:$D, $D8, '3월 단양 개인별 STAT'!$E:$E, $E8) + SUMIFS('4월 삼척 개인별 STAT'!O:O, '4월 삼척 개인별 STAT'!$D:$D, $D8, '4월 삼척 개인별 STAT'!$E:$E, $E8) -> 0 | P8: =SUMIFS('3월 단양 개인별 STAT'!P:P, '3월 단양 개인별 STAT'!$D:$D, $D8, '3월 단양 개인별 STAT'!$E:$E, $E8) + SUMIFS('4월 삼척 개인별 STAT'!P:P, '4월 삼척 개인별 STAT'!$D:$D, $D8, '4월 삼척 개인별 STAT'!$E:$E, $E8) -> 0 | Q8: =SUMIFS('3월 단양 개인별 STAT'!Q:Q, '3월 단양 개인별 STAT'!$D:$D, $D8, '3월 단양 개인별 STAT'!$E:$E, $E8) + SUMIFS('4월 삼척 개인별 STAT'!Q:Q, '4월 삼척 개인별 STAT'!$D:$D, $D8, '4월 삼척 개인별 STAT'!$E:$E, $E8) -> 0 | R8: =if(Q8+P8+N8=0,"-",Q8+P8+N8) -> - | S8: =if(iferror((N8-Q8)/R8,0)=0,"-",round((N8-Q8)/R8,2)) -> - | T8: =SUMIFS('3월 단양 개인별 STAT'!T:T, '3월 단양 개인별 STAT'!$D:$D, $D8, '3월 단양 개인별 STAT'!$E:$E, $E8) + SUMIFS('4월 삼척 개인별 STAT'!T:T, '4월 삼척 개인별 STAT'!$D:$D, $D8, '4월 삼척 개인별 STAT'!$E:$E, $E8) -> 0 | U8: =SUMIFS('3월 단양 개인별 STAT'!U:U, '3월 단양 개인별 STAT'!$D:$D, $D8, '3월 단양 개인별 STAT'!$E:$E, $E8) + SUMIFS('4월 삼척 개인별 STAT'!U:U, '4월 삼척 개인별 STAT'!$D:$D, $D8, '4월 삼척 개인별 STAT'!$E:$E, $E8) -> 0 | V8: =SUMIFS('3월 단양 개인별 STAT'!V:V, '3월 단양 개인별 STAT'!$D:$D, $D8, '3월 단양 개인별 STAT'!$E:$E, $E8) + SUMIFS('4월 삼척 개인별 STAT'!V:V, '4월 삼척 개인별 STAT'!$D:$D, $D8, '4월 삼척 개인별 STAT'!$E:$E, $E8) -> 0 | W8: =SUMIFS('3월 단양 개인별 STAT'!W:W, '3월 단양 개인별 STAT'!$D:$D, $D8, '3월 단양 개인별 STAT'!$E:$E, $E8) + SUMIFS('4월 삼척 개인별 STAT'!W:W, '4월 삼척 개인별 STAT'!$D:$D, $D8, '4월 삼척 개인별 STAT'!$E:$E, $E8) -> 12 | X8: =SUMIFS('3월 단양 개인별 STAT'!X:X, '3월 단양 개인별 STAT'!$D:$D, $D8, '3월 단양 개인별 STAT'!$E:$E, $E8) + SUMIFS('4월 삼척 개인별 STAT'!X:X, '4월 삼척 개인별 STAT'!$D:$D, $D8, '4월 삼척 개인별 STAT'!$E:$E, $E8) -> 1 | Y8: =SUMIFS('3월 단양 개인별 STAT'!Y:Y, '3월 단양 개인별 STAT'!$D:$D, $D8, '3월 단양 개인별 STAT'!$E:$E, $E8) + SUMIFS('4월 삼척 개인별 STAT'!Y:Y, '4월 삼척 개인별 STAT'!$D:$D, $D8, '4월 삼척 개인별 STAT'!$E:$E, $E8) -> 0 | Z8: =IF(Y8+X8+W8=0,"-",Y8+X8+W8) -> 13 | AA8: =SUMIFS('3월 단양 개인별 STAT'!AA:AA, '3월 단양 개인별 STAT'!$D:$D, $D8, '3월 단양 개인별 STAT'!$E:$E, $E8) + SUMIFS('4월 삼척 개인별 STAT'!AA:AA, '4월 삼척 개인별 STAT'!$D:$D, $D8, '4월 삼척 개인별 STAT'!$E:$E, $E8) -> 0 | AB8: =if((T8+X8+N8)=0, "-",T8+X8+N8) -> 1 | AC8: =N8+T8+X8+(V8*0.75) -> 1 | AD8: =IF(AE8+AF8=0,"-",AE8+AF8) -> 9 | AE8: =SUMIFS('3월 단양 개인별 STAT'!AE:AE, '3월 단양 개인별 STAT'!$D:$D, $D8, '3월 단양 개인별 STAT'!$E:$E, $E8) + SUMIFS('4월 삼척 개인별 STAT'!AE:AE, '4월 삼척 개인별 STAT'!$D:$D, $D8, '4월 삼척 개인별 STAT'!$E:$E, $E8) -> 8 | AF8: =SUMIFS('3월 단양 개인별 STAT'!AF:AF, '3월 단양 개인별 STAT'!$D:$D, $D8, '3월 단양 개인별 STAT'!$E:$E, $E8) + SUMIFS('4월 삼척 개인별 STAT'!AF:AF, '4월 삼척 개인별 STAT'!$D:$D, $D8, '4월 삼척 개인별 STAT'!$E:$E, $E8) -> 1 | AG8: =iferror((AE8/AD8)*100,"-") -> 88.888889 | AH8: =SUMIFS('3월 단양 개인별 STAT'!AH:AH, '3월 단양 개인별 STAT'!$D:$D, $D8, '3월 단양 개인별 STAT'!$E:$E, $E8) + SUMIFS('4월 삼척 개인별 STAT'!AH:AH, '4월 삼척 개인별 STAT'!$D:$D, $D8, '4월 삼척 개인별 STAT'!$E:$E, $E8) -> 5 | AI8: =IFERROR(IF(MOD(AH8/M8, 1)=0, TEXT(AH8/M8, "0"), TEXT(AH8/M8, "0.00")), "-") -> 0.83 | AL8: =iferror(N8/$M8,"-") -> 0 | AM8: =iferror(R8/$M8,"-") -> - | AN8: =iferror(N8/R8,"-") -> - | AO8: =iferror(T8/$M8,"-") -> 0 | AP8: =iferror(X8/$M8,"-") -> 0.16666667 | AQ8: =iferror(AB8/$M8,"-") -> 0.16666667 | AR8: =iferror(AC8/$M8,"-") -> 0.16666667 | AS8: =iferror(AF8/M8,"-") -> 0.16666667 | AT8: =AI8 -> 0.83
B9: 6 | C9: =if(D9=D8,C8+1,1) -> 6 | D9: 선명여고 | E9: 김예서 | F9: 3 | G9: OP | H9: - | I9: 181 | J9: 67 | K9: 9 | L9: =SUMIFS('3월 단양 개인별 STAT'!L:L, '3월 단양 개인별 STAT'!$D:$D, $D9, '3월 단양 개인별 STAT'!$E:$E, $E9) + SUMIFS('4월 삼척 개인별 STAT'!L:L, '4월 삼척 개인별 STAT'!$D:$D, $D9, '4월 삼척 개인별 STAT'!$E:$E, $E9) -> 2 | M9: =SUMIFS('3월 단양 개인별 STAT'!M:M, '3월 단양 개인별 STAT'!$D:$D, $D9, '3월 단양 개인별 STAT'!$E:$E, $E9) + SUMIFS('4월 삼척 개인별 STAT'!M:M, '4월 삼척 개인별 STAT'!$D:$D, $D9, '4월 삼척 개인별 STAT'!$E:$E, $E9) -> 4 | N9: =SUMIFS('3월 단양 개인별 STAT'!N:N, '3월 단양 개인별 STAT'!$D:$D, $D9, '3월 단양 개인별 STAT'!$E:$E, $E9) + SUMIFS('4월 삼척 개인별 STAT'!N:N, '4월 삼척 개인별 STAT'!$D:$D, $D9, '4월 삼척 개인별 STAT'!$E:$E, $E9) -> 0 | O9: =SUMIFS('3월 단양 개인별 STAT'!O:O, '3월 단양 개인별 STAT'!$D:$D, $D9, '3월 단양 개인별 STAT'!$E:$E, $E9) + SUMIFS('4월 삼척 개인별 STAT'!O:O, '4월 삼척 개인별 STAT'!$D:$D, $D9, '4월 삼척 개인별 STAT'!$E:$E, $E9) -> 0 | P9: =SUMIFS('3월 단양 개인별 STAT'!P:P, '3월 단양 개인별 STAT'!$D:$D, $D9, '3월 단양 개인별 STAT'!$E:$E, $E9) + SUMIFS('4월 삼척 개인별 STAT'!P:P, '4월 삼척 개인별 STAT'!$D:$D, $D9, '4월 삼척 개인별 STAT'!$E:$E, $E9) -> 0 | Q9: =SUMIFS('3월 단양 개인별 STAT'!Q:Q, '3월 단양 개인별 STAT'!$D:$D, $D9, '3월 단양 개인별 STAT'!$E:$E, $E9) + SUMIFS('4월 삼척 개인별 STAT'!Q:Q, '4월 삼척 개인별 STAT'!$D:$D, $D9, '4월 삼척 개인별 STAT'!$E:$E, $E9) -> 0 | R9: =if(Q9+P9+N9=0,"-",Q9+P9+N9) -> - | S9: =if(iferror((N9-Q9)/R9,0)=0,"-",round((N9-Q9)/R9,2)) -> - | T9: =SUMIFS('3월 단양 개인별 STAT'!T:T, '3월 단양 개인별 STAT'!$D:$D, $D9, '3월 단양 개인별 STAT'!$E:$E, $E9) + SUMIFS('4월 삼척 개인별 STAT'!T:T, '4월 삼척 개인별 STAT'!$D:$D, $D9, '4월 삼척 개인별 STAT'!$E:$E, $E9) -> 0 | U9: =SUMIFS('3월 단양 개인별 STAT'!U:U, '3월 단양 개인별 STAT'!$D:$D, $D9, '3월 단양 개인별 STAT'!$E:$E, $E9) + SUMIFS('4월 삼척 개인별 STAT'!U:U, '4월 삼척 개인별 STAT'!$D:$D, $D9, '4월 삼척 개인별 STAT'!$E:$E, $E9) -> 0 | V9: =SUMIFS('3월 단양 개인별 STAT'!V:V, '3월 단양 개인별 STAT'!$D:$D, $D9, '3월 단양 개인별 STAT'!$E:$E, $E9) + SUMIFS('4월 삼척 개인별 STAT'!V:V, '4월 삼척 개인별 STAT'!$D:$D, $D9, '4월 삼척 개인별 STAT'!$E:$E, $E9) -> 0 | W9: =SUMIFS('3월 단양 개인별 STAT'!W:W, '3월 단양 개인별 STAT'!$D:$D, $D9, '3월 단양 개인별 STAT'!$E:$E, $E9) + SUMIFS('4월 삼척 개인별 STAT'!W:W, '4월 삼척 개인별 STAT'!$D:$D, $D9, '4월 삼척 개인별 STAT'!$E:$E, $E9) -> 6 | X9: =SUMIFS('3월 단양 개인별 STAT'!X:X, '3월 단양 개인별 STAT'!$D:$D, $D9, '3월 단양 개인별 STAT'!$E:$E, $E9) + SUMIFS('4월 삼척 개인별 STAT'!X:X, '4월 삼척 개인별 STAT'!$D:$D, $D9, '4월 삼척 개인별 STAT'!$E:$E, $E9) -> 3 | Y9: =SUMIFS('3월 단양 개인별 STAT'!Y:Y, '3월 단양 개인별 STAT'!$D:$D, $D9, '3월 단양 개인별 STAT'!$E:$E, $E9) + SUMIFS('4월 삼척 개인별 STAT'!Y:Y, '4월 삼척 개인별 STAT'!$D:$D, $D9, '4월 삼척 개인별 STAT'!$E:$E, $E9) -> 1 | Z9: =IF(Y9+X9+W9=0,"-",Y9+X9+W9) -> 10 | AA9: =SUMIFS('3월 단양 개인별 STAT'!AA:AA, '3월 단양 개인별 STAT'!$D:$D, $D9, '3월 단양 개인별 STAT'!$E:$E, $E9) + SUMIFS('4월 삼척 개인별 STAT'!AA:AA, '4월 삼척 개인별 STAT'!$D:$D, $D9, '4월 삼척 개인별 STAT'!$E:$E, $E9) -> 0 | AB9: =if((T9+X9+N9)=0, "-",T9+X9+N9) -> 3 | AC9: =N9+T9+X9+(V9*0.75) -> 3 | AD9: =IF(AE9+AF9=0,"-",AE9+AF9) -> 1 | AE9: =SUMIFS('3월 단양 개인별 STAT'!AE:AE, '3월 단양 개인별 STAT'!$D:$D, $D9, '3월 단양 개인별 STAT'!$E:$E, $E9) + SUMIFS('4월 삼척 개인별 STAT'!AE:AE, '4월 삼척 개인별 STAT'!$D:$D, $D9, '4월 삼척 개인별 STAT'!$E:$E, $E9) -> 1 | AF9: =SUMIFS('3월 단양 개인별 STAT'!AF:AF, '3월 단양 개인별 STAT'!$D:$D, $D9, '3월 단양 개인별 STAT'!$E:$E, $E9) + SUMIFS('4월 삼척 개인별 STAT'!AF:AF, '4월 삼척 개인별 STAT'!$D:$D, $D9, '4월 삼척 개인별 STAT'!$E:$E, $E9) -> 0 | AG9: =iferror((AE9/AD9)*100,"-") -> 100 | AH9: =SUMIFS('3월 단양 개인별 STAT'!AH:AH, '3월 단양 개인별 STAT'!$D:$D, $D9, '3월 단양 개인별 STAT'!$E:$E, $E9) + SUMIFS('4월 삼척 개인별 STAT'!AH:AH, '4월 삼척 개인별 STAT'!$D:$D, $D9, '4월 삼척 개인별 STAT'!$E:$E, $E9) -> 0 | AI9: =IFERROR(IF(MOD(AH9/M9, 1)=0, TEXT(AH9/M9, "0"), TEXT(AH9/M9, "0.00")), "-") -> 0 | AL9: =iferror(N9/$M9,"-") -> 0 | AM9: =iferror(R9/$M9,"-") -> - | AN9: =iferror(N9/R9,"-") -> - | AO9: =iferror(T9/$M9,"-") -> 0 | AP9: =iferror(X9/$M9,"-") -> 0.75 | AQ9: =iferror(AB9/$M9,"-") -> 0.75 | AR9: =iferror(AC9/$M9,"-") -> 0.75 | AS9: =iferror(AF9/M9,"-") -> 0 | AT9: =AI9 -> 0
B10: 7 | C10: =if(D10=D9,C9+1,1) -> 7 | D10: 선명여고 | E10: 유정인 | F10: 2 | G10: MB | H10: - | I10: 183 | J10: 65 | K10: 10 | L10: =SUMIFS('3월 단양 개인별 STAT'!L:L, '3월 단양 개인별 STAT'!$D:$D, $D10, '3월 단양 개인별 STAT'!$E:$E, $E10) + SUMIFS('4월 삼척 개인별 STAT'!L:L, '4월 삼척 개인별 STAT'!$D:$D, $D10, '4월 삼척 개인별 STAT'!$E:$E, $E10) -> 1 | M10: =SUMIFS('3월 단양 개인별 STAT'!M:M, '3월 단양 개인별 STAT'!$D:$D, $D10, '3월 단양 개인별 STAT'!$E:$E, $E10) + SUMIFS('4월 삼척 개인별 STAT'!M:M, '4월 삼척 개인별 STAT'!$D:$D, $D10, '4월 삼척 개인별 STAT'!$E:$E, $E10) -> 3 | N10: =SUMIFS('3월 단양 개인별 STAT'!N:N, '3월 단양 개인별 STAT'!$D:$D, $D10, '3월 단양 개인별 STAT'!$E:$E, $E10) + SUMIFS('4월 삼척 개인별 STAT'!N:N, '4월 삼척 개인별 STAT'!$D:$D, $D10, '4월 삼척 개인별 STAT'!$E:$E, $E10) -> 8 | O10: =SUMIFS('3월 단양 개인별 STAT'!O:O, '3월 단양 개인별 STAT'!$D:$D, $D10, '3월 단양 개인별 STAT'!$E:$E, $E10) + SUMIFS('4월 삼척 개인별 STAT'!O:O, '4월 삼척 개인별 STAT'!$D:$D, $D10, '4월 삼척 개인별 STAT'!$E:$E, $E10) -> 0 | P10: =SUMIFS('3월 단양 개인별 STAT'!P:P, '3월 단양 개인별 STAT'!$D:$D, $D10, '3월 단양 개인별 STAT'!$E:$E, $E10) + SUMIFS('4월 삼척 개인별 STAT'!P:P, '4월 삼척 개인별 STAT'!$D:$D, $D10, '4월 삼척 개인별 STAT'!$E:$E, $E10) -> 3 | Q10: =SUMIFS('3월 단양 개인별 STAT'!Q:Q, '3월 단양 개인별 STAT'!$D:$D, $D10, '3월 단양 개인별 STAT'!$E:$E, $E10) + SUMIFS('4월 삼척 개인별 STAT'!Q:Q, '4월 삼척 개인별 STAT'!$D:$D, $D10, '4월 삼척 개인별 STAT'!$E:$E, $E10) -> 1 | R10: =if(Q10+P10+N10=0,"-",Q10+P10+N10) -> 12 | S10: =if(iferror((N10-Q10)/R10,0)=0,"-",round((N10-Q10)/R10,2)) -> 0.58 | T10: =SUMIFS('3월 단양 개인별 STAT'!T:T, '3월 단양 개인별 STAT'!$D:$D, $D10, '3월 단양 개인별 STAT'!$E:$E, $E10) + SUMIFS('4월 삼척 개인별 STAT'!T:T, '4월 삼척 개인별 STAT'!$D:$D, $D10, '4월 삼척 개인별 STAT'!$E:$E, $E10) -> 1 | U10: =SUMIFS('3월 단양 개인별 STAT'!U:U, '3월 단양 개인별 STAT'!$D:$D, $D10, '3월 단양 개인별 STAT'!$E:$E, $E10) + SUMIFS('4월 삼척 개인별 STAT'!U:U, '4월 삼척 개인별 STAT'!$D:$D, $D10, '4월 삼척 개인별 STAT'!$E:$E, $E10) -> 0 | V10: =SUMIFS('3월 단양 개인별 STAT'!V:V, '3월 단양 개인별 STAT'!$D:$D, $D10, '3월 단양 개인별 STAT'!$E:$E, $E10) + SUMIFS('4월 삼척 개인별 STAT'!V:V, '4월 삼척 개인별 STAT'!$D:$D, $D10, '4월 삼척 개인별 STAT'!$E:$E, $E10) -> 0 | W10: =SUMIFS('3월 단양 개인별 STAT'!W:W, '3월 단양 개인별 STAT'!$D:$D, $D10, '3월 단양 개인별 STAT'!$E:$E, $E10) + SUMIFS('4월 삼척 개인별 STAT'!W:W, '4월 삼척 개인별 STAT'!$D:$D, $D10, '4월 삼척 개인별 STAT'!$E:$E, $E10) -> 2 | X10: =SUMIFS('3월 단양 개인별 STAT'!X:X, '3월 단양 개인별 STAT'!$D:$D, $D10, '3월 단양 개인별 STAT'!$E:$E, $E10) + SUMIFS('4월 삼척 개인별 STAT'!X:X, '4월 삼척 개인별 STAT'!$D:$D, $D10, '4월 삼척 개인별 STAT'!$E:$E, $E10) -> 0 | Y10: =SUMIFS('3월 단양 개인별 STAT'!Y:Y, '3월 단양 개인별 STAT'!$D:$D, $D10, '3월 단양 개인별 STAT'!$E:$E, $E10) + SUMIFS('4월 삼척 개인별 STAT'!Y:Y, '4월 삼척 개인별 STAT'!$D:$D, $D10, '4월 삼척 개인별 STAT'!$E:$E, $E10) -> 0 | Z10: =IF(Y10+X10+W10=0,"-",Y10+X10+W10) -> 2 | AA10: =SUMIFS('3월 단양 개인별 STAT'!AA:AA, '3월 단양 개인별 STAT'!$D:$D, $D10, '3월 단양 개인별 STAT'!$E:$E, $E10) + SUMIFS('4월 삼척 개인별 STAT'!AA:AA, '4월 삼척 개인별 STAT'!$D:$D, $D10, '4월 삼척 개인별 STAT'!$E:$E, $E10) -> 0 | AB10: =if((T10+X10+N10)=0, "-",T10+X10+N10) -> 9 | AC10: =N10+T10+X10+(V10*0.75) -> 9 | AD10: =IF(AE10+AF10=0,"-",AE10+AF10) -> - | AE10: =SUMIFS('3월 단양 개인별 STAT'!AE:AE, '3월 단양 개인별 STAT'!$D:$D, $D10, '3월 단양 개인별 STAT'!$E:$E, $E10) + SUMIFS('4월 삼척 개인별 STAT'!AE:AE, '4월 삼척 개인별 STAT'!$D:$D, $D10, '4월 삼척 개인별 STAT'!$E:$E, $E10) -> 0 | AF10: =SUMIFS('3월 단양 개인별 STAT'!AF:AF, '3월 단양 개인별 STAT'!$D:$D, $D10, '3월 단양 개인별 STAT'!$E:$E, $E10) + SUMIFS('4월 삼척 개인별 STAT'!AF:AF, '4월 삼척 개인별 STAT'!$D:$D, $D10, '4월 삼척 개인별 STAT'!$E:$E, $E10) -> 0 | AG10: =iferror((AE10/AD10)*100,"-") -> - | AH10: =SUMIFS('3월 단양 개인별 STAT'!AH:AH, '3월 단양 개인별 STAT'!$D:$D, $D10, '3월 단양 개인별 STAT'!$E:$E, $E10) + SUMIFS('4월 삼척 개인별 STAT'!AH:AH, '4월 삼척 개인별 STAT'!$D:$D, $D10, '4월 삼척 개인별 STAT'!$E:$E, $E10) -> 1 | AI10: =IFERROR(IF(MOD(AH10/M10, 1)=0, TEXT(AH10/M10, "0"), TEXT(AH10/M10, "0.00")), "-") -> 0.33 | AL10: =iferror(N10/$M10,"-") -> 2.6666667 | AM10: =iferror(R10/$M10,"-") -> 4 | AN10: =iferror(N10/R10,"-") -> 0.66666667 | AO10: =iferror(T10/$M10,"-") -> 0.33333333 | AP10: =iferror(X10/$M10,"-") -> 0 | AQ10: =iferror(AB10/$M10,"-") -> 3 | AR10: =iferror(AC10/$M10,"-") -> 3 | AS10: =iferror(AF10/M10,"-") -> 0 | AT10: =AI10 -> 0.33
B11: 8 | C11: =if(D11=D10,C10+1,1) -> 8 | D11: 선명여고 | E11: 이서인 | F11: 1 | G11: S | H11: - | I11: 178 | J11: 64 | K11: 11 | L11: =SUMIFS('3월 단양 개인별 STAT'!L:L, '3월 단양 개인별 STAT'!$D:$D, $D11, '3월 단양 개인별 STAT'!$E:$E, $E11) + SUMIFS('4월 삼척 개인별 STAT'!L:L, '4월 삼척 개인별 STAT'!$D:$D, $D11, '4월 삼척 개인별 STAT'!$E:$E, $E11) -> 1 | M11: =SUMIFS('3월 단양 개인별 STAT'!M:M, '3월 단양 개인별 STAT'!$D:$D, $D11, '3월 단양 개인별 STAT'!$E:$E, $E11) + SUMIFS('4월 삼척 개인별 STAT'!M:M, '4월 삼척 개인별 STAT'!$D:$D, $D11, '4월 삼척 개인별 STAT'!$E:$E, $E11) -> 2 | N11: =SUMIFS('3월 단양 개인별 STAT'!N:N, '3월 단양 개인별 STAT'!$D:$D, $D11, '3월 단양 개인별 STAT'!$E:$E, $E11) + SUMIFS('4월 삼척 개인별 STAT'!N:N, '4월 삼척 개인별 STAT'!$D:$D, $D11, '4월 삼척 개인별 STAT'!$E:$E, $E11) -> 0 | O11: =SUMIFS('3월 단양 개인별 STAT'!O:O, '3월 단양 개인별 STAT'!$D:$D, $D11, '3월 단양 개인별 STAT'!$E:$E, $E11) + SUMIFS('4월 삼척 개인별 STAT'!O:O, '4월 삼척 개인별 STAT'!$D:$D, $D11, '4월 삼척 개인별 STAT'!$E:$E, $E11) -> 17 | P11: =SUMIFS('3월 단양 개인별 STAT'!P:P, '3월 단양 개인별 STAT'!$D:$D, $D11, '3월 단양 개인별 STAT'!$E:$E, $E11) + SUMIFS('4월 삼척 개인별 STAT'!P:P, '4월 삼척 개인별 STAT'!$D:$D, $D11, '4월 삼척 개인별 STAT'!$E:$E, $E11) -> 2 | Q11: =SUMIFS('3월 단양 개인별 STAT'!Q:Q, '3월 단양 개인별 STAT'!$D:$D, $D11, '3월 단양 개인별 STAT'!$E:$E, $E11) + SUMIFS('4월 삼척 개인별 STAT'!Q:Q, '4월 삼척 개인별 STAT'!$D:$D, $D11, '4월 삼척 개인별 STAT'!$E:$E, $E11) -> 1 | R11: =if(Q11+P11+N11=0,"-",Q11+P11+N11) -> 3 | S11: =if(iferror((N11-Q11)/R11,0)=0,"-",round((N11-Q11)/R11,2)) -> -0.33 | T11: =SUMIFS('3월 단양 개인별 STAT'!T:T, '3월 단양 개인별 STAT'!$D:$D, $D11, '3월 단양 개인별 STAT'!$E:$E, $E11) + SUMIFS('4월 삼척 개인별 STAT'!T:T, '4월 삼척 개인별 STAT'!$D:$D, $D11, '4월 삼척 개인별 STAT'!$E:$E, $E11) -> 0 | U11: =SUMIFS('3월 단양 개인별 STAT'!U:U, '3월 단양 개인별 STAT'!$D:$D, $D11, '3월 단양 개인별 STAT'!$E:$E, $E11) + SUMIFS('4월 삼척 개인별 STAT'!U:U, '4월 삼척 개인별 STAT'!$D:$D, $D11, '4월 삼척 개인별 STAT'!$E:$E, $E11) -> 0 | V11: =SUMIFS('3월 단양 개인별 STAT'!V:V, '3월 단양 개인별 STAT'!$D:$D, $D11, '3월 단양 개인별 STAT'!$E:$E, $E11) + SUMIFS('4월 삼척 개인별 STAT'!V:V, '4월 삼척 개인별 STAT'!$D:$D, $D11, '4월 삼척 개인별 STAT'!$E:$E, $E11) -> 0 | W11: =SUMIFS('3월 단양 개인별 STAT'!W:W, '3월 단양 개인별 STAT'!$D:$D, $D11, '3월 단양 개인별 STAT'!$E:$E, $E11) + SUMIFS('4월 삼척 개인별 STAT'!W:W, '4월 삼척 개인별 STAT'!$D:$D, $D11, '4월 삼척 개인별 STAT'!$E:$E, $E11) -> 3 | X11: =SUMIFS('3월 단양 개인별 STAT'!X:X, '3월 단양 개인별 STAT'!$D:$D, $D11, '3월 단양 개인별 STAT'!$E:$E, $E11) + SUMIFS('4월 삼척 개인별 STAT'!X:X, '4월 삼척 개인별 STAT'!$D:$D, $D11, '4월 삼척 개인별 STAT'!$E:$E, $E11) -> 0 | Y11: =SUMIFS('3월 단양 개인별 STAT'!Y:Y, '3월 단양 개인별 STAT'!$D:$D, $D11, '3월 단양 개인별 STAT'!$E:$E, $E11) + SUMIFS('4월 삼척 개인별 STAT'!Y:Y, '4월 삼척 개인별 STAT'!$D:$D, $D11, '4월 삼척 개인별 STAT'!$E:$E, $E11) -> 1 | Z11: =IF(Y11+X11+W11=0,"-",Y11+X11+W11) -> 4 | AA11: =SUMIFS('3월 단양 개인별 STAT'!AA:AA, '3월 단양 개인별 STAT'!$D:$D, $D11, '3월 단양 개인별 STAT'!$E:$E, $E11) + SUMIFS('4월 삼척 개인별 STAT'!AA:AA, '4월 삼척 개인별 STAT'!$D:$D, $D11, '4월 삼척 개인별 STAT'!$E:$E, $E11) -> 1 | AB11: =if((T11+X11+N11)=0, "-",T11+X11+N11) -> - | AC11: =N11+T11+X11+(V11*0.75) -> 0 | AD11: =IF(AE11+AF11=0,"-",AE11+AF11) -> 2 | AE11: =SUMIFS('3월 단양 개인별 STAT'!AE:AE, '3월 단양 개인별 STAT'!$D:$D, $D11, '3월 단양 개인별 STAT'!$E:$E, $E11) + SUMIFS('4월 삼척 개인별 STAT'!AE:AE, '4월 삼척 개인별 STAT'!$D:$D, $D11, '4월 삼척 개인별 STAT'!$E:$E, $E11) -> 1 | AF11: =SUMIFS('3월 단양 개인별 STAT'!AF:AF, '3월 단양 개인별 STAT'!$D:$D, $D11, '3월 단양 개인별 STAT'!$E:$E, $E11) + SUMIFS('4월 삼척 개인별 STAT'!AF:AF, '4월 삼척 개인별 STAT'!$D:$D, $D11, '4월 삼척 개인별 STAT'!$E:$E, $E11) -> 1 | AG11: =iferror((AE11/AD11)*100,"-") -> 50 | AH11: =SUMIFS('3월 단양 개인별 STAT'!AH:AH, '3월 단양 개인별 STAT'!$D:$D, $D11, '3월 단양 개인별 STAT'!$E:$E, $E11) + SUMIFS('4월 삼척 개인별 STAT'!AH:AH, '4월 삼척 개인별 STAT'!$D:$D, $D11, '4월 삼척 개인별 STAT'!$E:$E, $E11) -> 4 | AI11: =IFERROR(IF(MOD(AH11/M11, 1)=0, TEXT(AH11/M11, "0"), TEXT(AH11/M11, "0.00")), "-") -> 2 | AL11: =iferror(N11/$M11,"-") -> 0 | AM11: =iferror(R11/$M11,"-") -> 1.5 | AN11: =iferror(N11/R11,"-") -> 0 | AO11: =iferror(T11/$M11,"-") -> 0 | AP11: =iferror(X11/$M11,"-") -> 0 | AQ11: =iferror(AB11/$M11,"-") -> - | AR11: =iferror(AC11/$M11,"-") -> 0 | AS11: =iferror(AF11/M11,"-") -> 0.5 | AT11: =AI11 -> 2
B12: 9 | C12: =if(D12=D11,C11+1,1) -> 9 | D12: 선명여고 | E12: 박은빈 | F12: 3 | G12: OH | H12: - | I12: 182 | J12: 67 | K12: 12 | L12: =SUMIFS('3월 단양 개인별 STAT'!L:L, '3월 단양 개인별 STAT'!$D:$D, $D12, '3월 단양 개인별 STAT'!$E:$E, $E12) + SUMIFS('4월 삼척 개인별 STAT'!L:L, '4월 삼척 개인별 STAT'!$D:$D, $D12, '4월 삼척 개인별 STAT'!$E:$E, $E12) -> 2 | M12: =SUMIFS('3월 단양 개인별 STAT'!M:M, '3월 단양 개인별 STAT'!$D:$D, $D12, '3월 단양 개인별 STAT'!$E:$E, $E12) + SUMIFS('4월 삼척 개인별 STAT'!M:M, '4월 삼척 개인별 STAT'!$D:$D, $D12, '4월 삼척 개인별 STAT'!$E:$E, $E12) -> 7 | N12: =SUMIFS('3월 단양 개인별 STAT'!N:N, '3월 단양 개인별 STAT'!$D:$D, $D12, '3월 단양 개인별 STAT'!$E:$E, $E12) + SUMIFS('4월 삼척 개인별 STAT'!N:N, '4월 삼척 개인별 STAT'!$D:$D, $D12, '4월 삼척 개인별 STAT'!$E:$E, $E12) -> 32 | O12: =SUMIFS('3월 단양 개인별 STAT'!O:O, '3월 단양 개인별 STAT'!$D:$D, $D12, '3월 단양 개인별 STAT'!$E:$E, $E12) + SUMIFS('4월 삼척 개인별 STAT'!O:O, '4월 삼척 개인별 STAT'!$D:$D, $D12, '4월 삼척 개인별 STAT'!$E:$E, $E12) -> 2 | P12: =SUMIFS('3월 단양 개인별 STAT'!P:P, '3월 단양 개인별 STAT'!$D:$D, $D12, '3월 단양 개인별 STAT'!$E:$E, $E12) + SUMIFS('4월 삼척 개인별 STAT'!P:P, '4월 삼척 개인별 STAT'!$D:$D, $D12, '4월 삼척 개인별 STAT'!$E:$E, $E12) -> 34 | Q12: =SUMIFS('3월 단양 개인별 STAT'!Q:Q, '3월 단양 개인별 STAT'!$D:$D, $D12, '3월 단양 개인별 STAT'!$E:$E, $E12) + SUMIFS('4월 삼척 개인별 STAT'!Q:Q, '4월 삼척 개인별 STAT'!$D:$D, $D12, '4월 삼척 개인별 STAT'!$E:$E, $E12) -> 13 | R12: =if(Q12+P12+N12=0,"-",Q12+P12+N12) -> 79 | S12: =if(iferror((N12-Q12)/R12,0)=0,"-",round((N12-Q12)/R12,2)) -> 0.24 | T12: =SUMIFS('3월 단양 개인별 STAT'!T:T, '3월 단양 개인별 STAT'!$D:$D, $D12, '3월 단양 개인별 STAT'!$E:$E, $E12) + SUMIFS('4월 삼척 개인별 STAT'!T:T, '4월 삼척 개인별 STAT'!$D:$D, $D12, '4월 삼척 개인별 STAT'!$E:$E, $E12) -> 2 | U12: =SUMIFS('3월 단양 개인별 STAT'!U:U, '3월 단양 개인별 STAT'!$D:$D, $D12, '3월 단양 개인별 STAT'!$E:$E, $E12) + SUMIFS('4월 삼척 개인별 STAT'!U:U, '4월 삼척 개인별 STAT'!$D:$D, $D12, '4월 삼척 개인별 STAT'!$E:$E, $E12) -> 1 | V12: =SUMIFS('3월 단양 개인별 STAT'!V:V, '3월 단양 개인별 STAT'!$D:$D, $D12, '3월 단양 개인별 STAT'!$E:$E, $E12) + SUMIFS('4월 삼척 개인별 STAT'!V:V, '4월 삼척 개인별 STAT'!$D:$D, $D12, '4월 삼척 개인별 STAT'!$E:$E, $E12) -> 0 | W12: =SUMIFS('3월 단양 개인별 STAT'!W:W, '3월 단양 개인별 STAT'!$D:$D, $D12, '3월 단양 개인별 STAT'!$E:$E, $E12) + SUMIFS('4월 삼척 개인별 STAT'!W:W, '4월 삼척 개인별 STAT'!$D:$D, $D12, '4월 삼척 개인별 STAT'!$E:$E, $E12) -> 18 | X12: =SUMIFS('3월 단양 개인별 STAT'!X:X, '3월 단양 개인별 STAT'!$D:$D, $D12, '3월 단양 개인별 STAT'!$E:$E, $E12) + SUMIFS('4월 삼척 개인별 STAT'!X:X, '4월 삼척 개인별 STAT'!$D:$D, $D12, '4월 삼척 개인별 STAT'!$E:$E, $E12) -> 1 | Y12: =SUMIFS('3월 단양 개인별 STAT'!Y:Y, '3월 단양 개인별 STAT'!$D:$D, $D12, '3월 단양 개인별 STAT'!$E:$E, $E12) + SUMIFS('4월 삼척 개인별 STAT'!Y:Y, '4월 삼척 개인별 STAT'!$D:$D, $D12, '4월 삼척 개인별 STAT'!$E:$E, $E12) -> 2 | Z12: =IF(Y12+X12+W12=0,"-",Y12+X12+W12) -> 21 | AA12: =SUMIFS('3월 단양 개인별 STAT'!AA:AA, '3월 단양 개인별 STAT'!$D:$D, $D12, '3월 단양 개인별 STAT'!$E:$E, $E12) + SUMIFS('4월 삼척 개인별 STAT'!AA:AA, '4월 삼척 개인별 STAT'!$D:$D, $D12, '4월 삼척 개인별 STAT'!$E:$E, $E12) -> 0 | AB12: =if((T12+X12+N12)=0, "-",T12+X12+N12) -> 35 | AC12: =N12+T12+X12+(V12*0.75) -> 35 | AD12: =IF(AE12+AF12=0,"-",AE12+AF12) -> 26 | AE12: =SUMIFS('3월 단양 개인별 STAT'!AE:AE, '3월 단양 개인별 STAT'!$D:$D, $D12, '3월 단양 개인별 STAT'!$E:$E, $E12) + SUMIFS('4월 삼척 개인별 STAT'!AE:AE, '4월 삼척 개인별 STAT'!$D:$D, $D12, '4월 삼척 개인별 STAT'!$E:$E, $E12) -> 23 | AF12: =SUMIFS('3월 단양 개인별 STAT'!AF:AF, '3월 단양 개인별 STAT'!$D:$D, $D12, '3월 단양 개인별 STAT'!$E:$E, $E12) + SUMIFS('4월 삼척 개인별 STAT'!AF:AF, '4월 삼척 개인별 STAT'!$D:$D, $D12, '4월 삼척 개인별 STAT'!$E:$E, $E12) -> 3 | AG12: =iferror((AE12/AD12)*100,"-") -> 88.461538 | AH12: =SUMIFS('3월 단양 개인별 STAT'!AH:AH, '3월 단양 개인별 STAT'!$D:$D, $D12, '3월 단양 개인별 STAT'!$E:$E, $E12) + SUMIFS('4월 삼척 개인별 STAT'!AH:AH, '4월 삼척 개인별 STAT'!$D:$D, $D12, '4월 삼척 개인별 STAT'!$E:$E, $E12) -> 11 | AI12: =IFERROR(IF(MOD(AH12/M12, 1)=0, TEXT(AH12/M12, "0"), TEXT(AH12/M12, "0.00")), "-") -> 1.57 | AL12: =iferror(N12/$M12,"-") -> 4.5714286 | AM12: =iferror(R12/$M12,"-") -> 11.285714 | AN12: =iferror(N12/R12,"-") -> 0.40506329 | AO12: =iferror(T12/$M12,"-") -> 0.28571429 | AP12: =iferror(X12/$M12,"-") -> 0.14285714 | AQ12: =iferror(AB12/$M12,"-") -> 5 | AR12: =iferror(AC12/$M12,"-") -> 5 | AS12: =iferror(AF12/M12,"-") -> 0.42857143 | AT12: =AI12 -> 1.57
B13: 10 | C13: =if(D13=D12,C12+1,1) -> 10 | D13: 선명여고 | E13: 김태경 | F13: 2 | G13: OP | H13: MB | I13: 184 | J13: 68 | K13: 13 | L13: =SUMIFS('3월 단양 개인별 STAT'!L:L, '3월 단양 개인별 STAT'!$D:$D, $D13, '3월 단양 개인별 STAT'!$E:$E, $E13) + SUMIFS('4월 삼척 개인별 STAT'!L:L, '4월 삼척 개인별 STAT'!$D:$D, $D13, '4월 삼척 개인별 STAT'!$E:$E, $E13) -> 2 | M13: =SUMIFS('3월 단양 개인별 STAT'!M:M, '3월 단양 개인별 STAT'!$D:$D, $D13, '3월 단양 개인별 STAT'!$E:$E, $E13) + SUMIFS('4월 삼척 개인별 STAT'!M:M, '4월 삼척 개인별 STAT'!$D:$D, $D13, '4월 삼척 개인별 STAT'!$E:$E, $E13) -> 7 | N13: =SUMIFS('3월 단양 개인별 STAT'!N:N, '3월 단양 개인별 STAT'!$D:$D, $D13, '3월 단양 개인별 STAT'!$E:$E, $E13) + SUMIFS('4월 삼척 개인별 STAT'!N:N, '4월 삼척 개인별 STAT'!$D:$D, $D13, '4월 삼척 개인별 STAT'!$E:$E, $E13) -> 12 | O13: =SUMIFS('3월 단양 개인별 STAT'!O:O, '3월 단양 개인별 STAT'!$D:$D, $D13, '3월 단양 개인별 STAT'!$E:$E, $E13) + SUMIFS('4월 삼척 개인별 STAT'!O:O, '4월 삼척 개인별 STAT'!$D:$D, $D13, '4월 삼척 개인별 STAT'!$E:$E, $E13) -> 1 | P13: =SUMIFS('3월 단양 개인별 STAT'!P:P, '3월 단양 개인별 STAT'!$D:$D, $D13, '3월 단양 개인별 STAT'!$E:$E, $E13) + SUMIFS('4월 삼척 개인별 STAT'!P:P, '4월 삼척 개인별 STAT'!$D:$D, $D13, '4월 삼척 개인별 STAT'!$E:$E, $E13) -> 14 | Q13: =SUMIFS('3월 단양 개인별 STAT'!Q:Q, '3월 단양 개인별 STAT'!$D:$D, $D13, '3월 단양 개인별 STAT'!$E:$E, $E13) + SUMIFS('4월 삼척 개인별 STAT'!Q:Q, '4월 삼척 개인별 STAT'!$D:$D, $D13, '4월 삼척 개인별 STAT'!$E:$E, $E13) -> 3 | R13: =if(Q13+P13+N13=0,"-",Q13+P13+N13) -> 29 | S13: =if(iferror((N13-Q13)/R13,0)=0,"-",round((N13-Q13)/R13,2)) -> 0.31 | T13: =SUMIFS('3월 단양 개인별 STAT'!T:T, '3월 단양 개인별 STAT'!$D:$D, $D13, '3월 단양 개인별 STAT'!$E:$E, $E13) + SUMIFS('4월 삼척 개인별 STAT'!T:T, '4월 삼척 개인별 STAT'!$D:$D, $D13, '4월 삼척 개인별 STAT'!$E:$E, $E13) -> 2 | U13: =SUMIFS('3월 단양 개인별 STAT'!U:U, '3월 단양 개인별 STAT'!$D:$D, $D13, '3월 단양 개인별 STAT'!$E:$E, $E13) + SUMIFS('4월 삼척 개인별 STAT'!U:U, '4월 삼척 개인별 STAT'!$D:$D, $D13, '4월 삼척 개인별 STAT'!$E:$E, $E13) -> 0 | V13: =SUMIFS('3월 단양 개인별 STAT'!V:V, '3월 단양 개인별 STAT'!$D:$D, $D13, '3월 단양 개인별 STAT'!$E:$E, $E13) + SUMIFS('4월 삼척 개인별 STAT'!V:V, '4월 삼척 개인별 STAT'!$D:$D, $D13, '4월 삼척 개인별 STAT'!$E:$E, $E13) -> 0 | W13: =SUMIFS('3월 단양 개인별 STAT'!W:W, '3월 단양 개인별 STAT'!$D:$D, $D13, '3월 단양 개인별 STAT'!$E:$E, $E13) + SUMIFS('4월 삼척 개인별 STAT'!W:W, '4월 삼척 개인별 STAT'!$D:$D, $D13, '4월 삼척 개인별 STAT'!$E:$E, $E13) -> 6 | X13: =SUMIFS('3월 단양 개인별 STAT'!X:X, '3월 단양 개인별 STAT'!$D:$D, $D13, '3월 단양 개인별 STAT'!$E:$E, $E13) + SUMIFS('4월 삼척 개인별 STAT'!X:X, '4월 삼척 개인별 STAT'!$D:$D, $D13, '4월 삼척 개인별 STAT'!$E:$E, $E13) -> 0 | Y13: =SUMIFS('3월 단양 개인별 STAT'!Y:Y, '3월 단양 개인별 STAT'!$D:$D, $D13, '3월 단양 개인별 STAT'!$E:$E, $E13) + SUMIFS('4월 삼척 개인별 STAT'!Y:Y, '4월 삼척 개인별 STAT'!$D:$D, $D13, '4월 삼척 개인별 STAT'!$E:$E, $E13) -> 5 | Z13: =IF(Y13+X13+W13=0,"-",Y13+X13+W13) -> 11 | AA13: =SUMIFS('3월 단양 개인별 STAT'!AA:AA, '3월 단양 개인별 STAT'!$D:$D, $D13, '3월 단양 개인별 STAT'!$E:$E, $E13) + SUMIFS('4월 삼척 개인별 STAT'!AA:AA, '4월 삼척 개인별 STAT'!$D:$D, $D13, '4월 삼척 개인별 STAT'!$E:$E, $E13) -> 1 | AB13: =if((T13+X13+N13)=0, "-",T13+X13+N13) -> 14 | AC13: =N13+T13+X13+(V13*0.75) -> 14 | AD13: =IF(AE13+AF13=0,"-",AE13+AF13) -> 5 | AE13: =SUMIFS('3월 단양 개인별 STAT'!AE:AE, '3월 단양 개인별 STAT'!$D:$D, $D13, '3월 단양 개인별 STAT'!$E:$E, $E13) + SUMIFS('4월 삼척 개인별 STAT'!AE:AE, '4월 삼척 개인별 STAT'!$D:$D, $D13, '4월 삼척 개인별 STAT'!$E:$E, $E13) -> 4 | AF13: =SUMIFS('3월 단양 개인별 STAT'!AF:AF, '3월 단양 개인별 STAT'!$D:$D, $D13, '3월 단양 개인별 STAT'!$E:$E, $E13) + SUMIFS('4월 삼척 개인별 STAT'!AF:AF, '4월 삼척 개인별 STAT'!$D:$D, $D13, '4월 삼척 개인별 STAT'!$E:$E, $E13) -> 1 | AG13: =iferror((AE13/AD13)*100,"-") -> 80 | AH13: =SUMIFS('3월 단양 개인별 STAT'!AH:AH, '3월 단양 개인별 STAT'!$D:$D, $D13, '3월 단양 개인별 STAT'!$E:$E, $E13) + SUMIFS('4월 삼척 개인별 STAT'!AH:AH, '4월 삼척 개인별 STAT'!$D:$D, $D13, '4월 삼척 개인별 STAT'!$E:$E, $E13) -> 7 | AI13: =IFERROR(IF(MOD(AH13/M13, 1)=0, TEXT(AH13/M13, "0"), TEXT(AH13/M13, "0.00")), "-") -> 1 | AL13: =iferror(N13/$M13,"-") -> 1.7142857 | AM13: =iferror(R13/$M13,"-") -> 4.1428571 | AN13: =iferror(N13/R13,"-") -> 0.4137931 | AO13: =iferror(T13/$M13,"-") -> 0.28571429 | AP13: =iferror(X13/$M13,"-") -> 0 | AQ13: =iferror(AB13/$M13,"-") -> 2 | AR13: =iferror(AC13/$M13,"-") -> 2 | AS13: =iferror(AF13/M13,"-") -> 0.14285714 | AT13: =AI13 -> 1
B14: 11 | C14: =if(D14=D13,C13+1,1) -> 11 | D14: 선명여고 | E14: 정세희 | F14: 3 | G14: S | H14: - | I14: 174 | J14: 60 | K14: 14 | L14: =SUMIFS('3월 단양 개인별 STAT'!L:L, '3월 단양 개인별 STAT'!$D:$D, $D14, '3월 단양 개인별 STAT'!$E:$E, $E14) + SUMIFS('4월 삼척 개인별 STAT'!L:L, '4월 삼척 개인별 STAT'!$D:$D, $D14, '4월 삼척 개인별 STAT'!$E:$E, $E14) -> 2 | M14: =SUMIFS('3월 단양 개인별 STAT'!M:M, '3월 단양 개인별 STAT'!$D:$D, $D14, '3월 단양 개인별 STAT'!$E:$E, $E14) + SUMIFS('4월 삼척 개인별 STAT'!M:M, '4월 삼척 개인별 STAT'!$D:$D, $D14, '4월 삼척 개인별 STAT'!$E:$E, $E14) -> 6 | N14: =SUMIFS('3월 단양 개인별 STAT'!N:N, '3월 단양 개인별 STAT'!$D:$D, $D14, '3월 단양 개인별 STAT'!$E:$E, $E14) + SUMIFS('4월 삼척 개인별 STAT'!N:N, '4월 삼척 개인별 STAT'!$D:$D, $D14, '4월 삼척 개인별 STAT'!$E:$E, $E14) -> 1 | O14: =SUMIFS('3월 단양 개인별 STAT'!O:O, '3월 단양 개인별 STAT'!$D:$D, $D14, '3월 단양 개인별 STAT'!$E:$E, $E14) + SUMIFS('4월 삼척 개인별 STAT'!O:O, '4월 삼척 개인별 STAT'!$D:$D, $D14, '4월 삼척 개인별 STAT'!$E:$E, $E14) -> 55 | P14: =SUMIFS('3월 단양 개인별 STAT'!P:P, '3월 단양 개인별 STAT'!$D:$D, $D14, '3월 단양 개인별 STAT'!$E:$E, $E14) + SUMIFS('4월 삼척 개인별 STAT'!P:P, '4월 삼척 개인별 STAT'!$D:$D, $D14, '4월 삼척 개인별 STAT'!$E:$E, $E14) -> 2 | Q14: =SUMIFS('3월 단양 개인별 STAT'!Q:Q, '3월 단양 개인별 STAT'!$D:$D, $D14, '3월 단양 개인별 STAT'!$E:$E, $E14) + SUMIFS('4월 삼척 개인별 STAT'!Q:Q, '4월 삼척 개인별 STAT'!$D:$D, $D14, '4월 삼척 개인별 STAT'!$E:$E, $E14) -> 0 | R14: =if(Q14+P14+N14=0,"-",Q14+P14+N14) -> 3 | S14: =if(iferror((N14-Q14)/R14,0)=0,"-",round((N14-Q14)/R14,2)) -> 0.33 | T14: =SUMIFS('3월 단양 개인별 STAT'!T:T, '3월 단양 개인별 STAT'!$D:$D, $D14, '3월 단양 개인별 STAT'!$E:$E, $E14) + SUMIFS('4월 삼척 개인별 STAT'!T:T, '4월 삼척 개인별 STAT'!$D:$D, $D14, '4월 삼척 개인별 STAT'!$E:$E, $E14) -> 0 | U14: =SUMIFS('3월 단양 개인별 STAT'!U:U, '3월 단양 개인별 STAT'!$D:$D, $D14, '3월 단양 개인별 STAT'!$E:$E, $E14) + SUMIFS('4월 삼척 개인별 STAT'!U:U, '4월 삼척 개인별 STAT'!$D:$D, $D14, '4월 삼척 개인별 STAT'!$E:$E, $E14) -> 0 | V14: =SUMIFS('3월 단양 개인별 STAT'!V:V, '3월 단양 개인별 STAT'!$D:$D, $D14, '3월 단양 개인별 STAT'!$E:$E, $E14) + SUMIFS('4월 삼척 개인별 STAT'!V:V, '4월 삼척 개인별 STAT'!$D:$D, $D14, '4월 삼척 개인별 STAT'!$E:$E, $E14) -> 0 | W14: =SUMIFS('3월 단양 개인별 STAT'!W:W, '3월 단양 개인별 STAT'!$D:$D, $D14, '3월 단양 개인별 STAT'!$E:$E, $E14) + SUMIFS('4월 삼척 개인별 STAT'!W:W, '4월 삼척 개인별 STAT'!$D:$D, $D14, '4월 삼척 개인별 STAT'!$E:$E, $E14) -> 32 | X14: =SUMIFS('3월 단양 개인별 STAT'!X:X, '3월 단양 개인별 STAT'!$D:$D, $D14, '3월 단양 개인별 STAT'!$E:$E, $E14) + SUMIFS('4월 삼척 개인별 STAT'!X:X, '4월 삼척 개인별 STAT'!$D:$D, $D14, '4월 삼척 개인별 STAT'!$E:$E, $E14) -> 1 | Y14: =SUMIFS('3월 단양 개인별 STAT'!Y:Y, '3월 단양 개인별 STAT'!$D:$D, $D14, '3월 단양 개인별 STAT'!$E:$E, $E14) + SUMIFS('4월 삼척 개인별 STAT'!Y:Y, '4월 삼척 개인별 STAT'!$D:$D, $D14, '4월 삼척 개인별 STAT'!$E:$E, $E14) -> 2 | Z14: =IF(Y14+X14+W14=0,"-",Y14+X14+W14) -> 35 | AA14: =SUMIFS('3월 단양 개인별 STAT'!AA:AA, '3월 단양 개인별 STAT'!$D:$D, $D14, '3월 단양 개인별 STAT'!$E:$E, $E14) + SUMIFS('4월 삼척 개인별 STAT'!AA:AA, '4월 삼척 개인별 STAT'!$D:$D, $D14, '4월 삼척 개인별 STAT'!$E:$E, $E14) -> 0 | AB14: =if((T14+X14+N14)=0, "-",T14+X14+N14) -> 2 | AC14: =N14+T14+X14+(V14*0.75) -> 2 | AD14: =IF(AE14+AF14=0,"-",AE14+AF14) -> - | AE14: =SUMIFS('3월 단양 개인별 STAT'!AE:AE, '3월 단양 개인별 STAT'!$D:$D, $D14, '3월 단양 개인별 STAT'!$E:$E, $E14) + SUMIFS('4월 삼척 개인별 STAT'!AE:AE, '4월 삼척 개인별 STAT'!$D:$D, $D14, '4월 삼척 개인별 STAT'!$E:$E, $E14) -> 0 | AF14: =SUMIFS('3월 단양 개인별 STAT'!AF:AF, '3월 단양 개인별 STAT'!$D:$D, $D14, '3월 단양 개인별 STAT'!$E:$E, $E14) + SUMIFS('4월 삼척 개인별 STAT'!AF:AF, '4월 삼척 개인별 STAT'!$D:$D, $D14, '4월 삼척 개인별 STAT'!$E:$E, $E14) -> 0 | AG14: =iferror((AE14/AD14)*100,"-") -> - | AH14: =SUMIFS('3월 단양 개인별 STAT'!AH:AH, '3월 단양 개인별 STAT'!$D:$D, $D14, '3월 단양 개인별 STAT'!$E:$E, $E14) + SUMIFS('4월 삼척 개인별 STAT'!AH:AH, '4월 삼척 개인별 STAT'!$D:$D, $D14, '4월 삼척 개인별 STAT'!$E:$E, $E14) -> 5 | AI14: =IFERROR(IF(MOD(AH14/M14, 1)=0, TEXT(AH14/M14, "0"), TEXT(AH14/M14, "0.00")), "-") -> 0.83 | AL14: =iferror(N14/$M14,"-") -> 0.16666667 | AM14: =iferror(R14/$M14,"-") -> 0.5 | AN14: =iferror(N14/R14,"-") -> 0.33333333 | AO14: =iferror(T14/$M14,"-") -> 0 | AP14: =iferror(X14/$M14,"-") -> 0.16666667 | AQ14: =iferror(AB14/$M14,"-") -> 0.33333333 | AR14: =iferror(AC14/$M14,"-") -> 0.33333333 | AS14: =iferror(AF14/M14,"-") -> 0 | AT14: =AI14 -> 0.83
B15: 12 | C15: =if(D15=D14,C14+1,1) -> 12 | D15: 선명여고 | E15: 손서연 | F15: 1 | G15: OH | H15: - | I15: 183 | J15: 67 | K15: 17 | L15: =SUMIFS('3월 단양 개인별 STAT'!L:L, '3월 단양 개인별 STAT'!$D:$D, $D15, '3월 단양 개인별 STAT'!$E:$E, $E15) + SUMIFS('4월 삼척 개인별 STAT'!L:L, '4월 삼척 개인별 STAT'!$D:$D, $D15, '4월 삼척 개인별 STAT'!$E:$E, $E15) -> 2 | M15: =SUMIFS('3월 단양 개인별 STAT'!M:M, '3월 단양 개인별 STAT'!$D:$D, $D15, '3월 단양 개인별 STAT'!$E:$E, $E15) + SUMIFS('4월 삼척 개인별 STAT'!M:M, '4월 삼척 개인별 STAT'!$D:$D, $D15, '4월 삼척 개인별 STAT'!$E:$E, $E15) -> 7 | N15: =SUMIFS('3월 단양 개인별 STAT'!N:N, '3월 단양 개인별 STAT'!$D:$D, $D15, '3월 단양 개인별 STAT'!$E:$E, $E15) + SUMIFS('4월 삼척 개인별 STAT'!N:N, '4월 삼척 개인별 STAT'!$D:$D, $D15, '4월 삼척 개인별 STAT'!$E:$E, $E15) -> 31 | O15: =SUMIFS('3월 단양 개인별 STAT'!O:O, '3월 단양 개인별 STAT'!$D:$D, $D15, '3월 단양 개인별 STAT'!$E:$E, $E15) + SUMIFS('4월 삼척 개인별 STAT'!O:O, '4월 삼척 개인별 STAT'!$D:$D, $D15, '4월 삼척 개인별 STAT'!$E:$E, $E15) -> 1 | P15: =SUMIFS('3월 단양 개인별 STAT'!P:P, '3월 단양 개인별 STAT'!$D:$D, $D15, '3월 단양 개인별 STAT'!$E:$E, $E15) + SUMIFS('4월 삼척 개인별 STAT'!P:P, '4월 삼척 개인별 STAT'!$D:$D, $D15, '4월 삼척 개인별 STAT'!$E:$E, $E15) -> 35 | Q15: =SUMIFS('3월 단양 개인별 STAT'!Q:Q, '3월 단양 개인별 STAT'!$D:$D, $D15, '3월 단양 개인별 STAT'!$E:$E, $E15) + SUMIFS('4월 삼척 개인별 STAT'!Q:Q, '4월 삼척 개인별 STAT'!$D:$D, $D15, '4월 삼척 개인별 STAT'!$E:$E, $E15) -> 11 | R15: =if(Q15+P15+N15=0,"-",Q15+P15+N15) -> 77 | S15: =if(iferror((N15-Q15)/R15,0)=0,"-",round((N15-Q15)/R15,2)) -> 0.26 | T15: =SUMIFS('3월 단양 개인별 STAT'!T:T, '3월 단양 개인별 STAT'!$D:$D, $D15, '3월 단양 개인별 STAT'!$E:$E, $E15) + SUMIFS('4월 삼척 개인별 STAT'!T:T, '4월 삼척 개인별 STAT'!$D:$D, $D15, '4월 삼척 개인별 STAT'!$E:$E, $E15) -> 6 | U15: =SUMIFS('3월 단양 개인별 STAT'!U:U, '3월 단양 개인별 STAT'!$D:$D, $D15, '3월 단양 개인별 STAT'!$E:$E, $E15) + SUMIFS('4월 삼척 개인별 STAT'!U:U, '4월 삼척 개인별 STAT'!$D:$D, $D15, '4월 삼척 개인별 STAT'!$E:$E, $E15) -> 1 | V15: =SUMIFS('3월 단양 개인별 STAT'!V:V, '3월 단양 개인별 STAT'!$D:$D, $D15, '3월 단양 개인별 STAT'!$E:$E, $E15) + SUMIFS('4월 삼척 개인별 STAT'!V:V, '4월 삼척 개인별 STAT'!$D:$D, $D15, '4월 삼척 개인별 STAT'!$E:$E, $E15) -> 0 | W15: =SUMIFS('3월 단양 개인별 STAT'!W:W, '3월 단양 개인별 STAT'!$D:$D, $D15, '3월 단양 개인별 STAT'!$E:$E, $E15) + SUMIFS('4월 삼척 개인별 STAT'!W:W, '4월 삼척 개인별 STAT'!$D:$D, $D15, '4월 삼척 개인별 STAT'!$E:$E, $E15) -> 22 | X15: =SUMIFS('3월 단양 개인별 STAT'!X:X, '3월 단양 개인별 STAT'!$D:$D, $D15, '3월 단양 개인별 STAT'!$E:$E, $E15) + SUMIFS('4월 삼척 개인별 STAT'!X:X, '4월 삼척 개인별 STAT'!$D:$D, $D15, '4월 삼척 개인별 STAT'!$E:$E, $E15) -> 1 | Y15: =SUMIFS('3월 단양 개인별 STAT'!Y:Y, '3월 단양 개인별 STAT'!$D:$D, $D15, '3월 단양 개인별 STAT'!$E:$E, $E15) + SUMIFS('4월 삼척 개인별 STAT'!Y:Y, '4월 삼척 개인별 STAT'!$D:$D, $D15, '4월 삼척 개인별 STAT'!$E:$E, $E15) -> 4 | Z15: =IF(Y15+X15+W15=0,"-",Y15+X15+W15) -> 27 | AA15: =SUMIFS('3월 단양 개인별 STAT'!AA:AA, '3월 단양 개인별 STAT'!$D:$D, $D15, '3월 단양 개인별 STAT'!$E:$E, $E15) + SUMIFS('4월 삼척 개인별 STAT'!AA:AA, '4월 삼척 개인별 STAT'!$D:$D, $D15, '4월 삼척 개인별 STAT'!$E:$E, $E15) -> 0 | AB15: =if((T15+X15+N15)=0, "-",T15+X15+N15) -> 38 | AC15: =N15+T15+X15+(V15*0.75) -> 38 | AD15: =IF(AE15+AF15=0,"-",AE15+AF15) -> 54 | AE15: =SUMIFS('3월 단양 개인별 STAT'!AE:AE, '3월 단양 개인별 STAT'!$D:$D, $D15, '3월 단양 개인별 STAT'!$E:$E, $E15) + SUMIFS('4월 삼척 개인별 STAT'!AE:AE, '4월 삼척 개인별 STAT'!$D:$D, $D15, '4월 삼척 개인별 STAT'!$E:$E, $E15) -> 50 | AF15: =SUMIFS('3월 단양 개인별 STAT'!AF:AF, '3월 단양 개인별 STAT'!$D:$D, $D15, '3월 단양 개인별 STAT'!$E:$E, $E15) + SUMIFS('4월 삼척 개인별 STAT'!AF:AF, '4월 삼척 개인별 STAT'!$D:$D, $D15, '4월 삼척 개인별 STAT'!$E:$E, $E15) -> 4 | AG15: =iferror((AE15/AD15)*100,"-") -> 92.592593 | AH15: =SUMIFS('3월 단양 개인별 STAT'!AH:AH, '3월 단양 개인별 STAT'!$D:$D, $D15, '3월 단양 개인별 STAT'!$E:$E, $E15) + SUMIFS('4월 삼척 개인별 STAT'!AH:AH, '4월 삼척 개인별 STAT'!$D:$D, $D15, '4월 삼척 개인별 STAT'!$E:$E, $E15) -> 17 | AI15: =IFERROR(IF(MOD(AH15/M15, 1)=0, TEXT(AH15/M15, "0"), TEXT(AH15/M15, "0.00")), "-") -> 2.43 | AL15: =iferror(N15/$M15,"-") -> 4.4285714 | AM15: ` | AN15: =iferror(N15/R15,"-") -> 0.4025974 | AO15: =iferror(T15/$M15,"-") -> 0.85714286 | AP15: =iferror(X15/$M15,"-") -> 0.14285714 | AQ15: =iferror(AB15/$M15,"-") -> 5.4285714 | AR15: =iferror(AC15/$M15,"-") -> 5.4285714 | AS15: =iferror(AF15/M15,"-") -> 0.57142857 | AT15: =AI15 -> 2.43
B16: 13 | C16: =if(D16=D15,C15+1,1) -> 13 | D16: 선명여고 | E16: 이서윤 | F16: 1 | G16: OP | H16: MB | I16: 172 | J16: 69 | K16: 18 | L16: =SUMIFS('3월 단양 개인별 STAT'!L:L, '3월 단양 개인별 STAT'!$D:$D, $D16, '3월 단양 개인별 STAT'!$E:$E, $E16) + SUMIFS('4월 삼척 개인별 STAT'!L:L, '4월 삼척 개인별 STAT'!$D:$D, $D16, '4월 삼척 개인별 STAT'!$E:$E, $E16) -> 1 | M16: =SUMIFS('3월 단양 개인별 STAT'!M:M, '3월 단양 개인별 STAT'!$D:$D, $D16, '3월 단양 개인별 STAT'!$E:$E, $E16) + SUMIFS('4월 삼척 개인별 STAT'!M:M, '4월 삼척 개인별 STAT'!$D:$D, $D16, '4월 삼척 개인별 STAT'!$E:$E, $E16) -> 4 | N16: =SUMIFS('3월 단양 개인별 STAT'!N:N, '3월 단양 개인별 STAT'!$D:$D, $D16, '3월 단양 개인별 STAT'!$E:$E, $E16) + SUMIFS('4월 삼척 개인별 STAT'!N:N, '4월 삼척 개인별 STAT'!$D:$D, $D16, '4월 삼척 개인별 STAT'!$E:$E, $E16) -> 0 | O16: =SUMIFS('3월 단양 개인별 STAT'!O:O, '3월 단양 개인별 STAT'!$D:$D, $D16, '3월 단양 개인별 STAT'!$E:$E, $E16) + SUMIFS('4월 삼척 개인별 STAT'!O:O, '4월 삼척 개인별 STAT'!$D:$D, $D16, '4월 삼척 개인별 STAT'!$E:$E, $E16) -> 2 | P16: =SUMIFS('3월 단양 개인별 STAT'!P:P, '3월 단양 개인별 STAT'!$D:$D, $D16, '3월 단양 개인별 STAT'!$E:$E, $E16) + SUMIFS('4월 삼척 개인별 STAT'!P:P, '4월 삼척 개인별 STAT'!$D:$D, $D16, '4월 삼척 개인별 STAT'!$E:$E, $E16) -> 4 | Q16: =SUMIFS('3월 단양 개인별 STAT'!Q:Q, '3월 단양 개인별 STAT'!$D:$D, $D16, '3월 단양 개인별 STAT'!$E:$E, $E16) + SUMIFS('4월 삼척 개인별 STAT'!Q:Q, '4월 삼척 개인별 STAT'!$D:$D, $D16, '4월 삼척 개인별 STAT'!$E:$E, $E16) -> 2 | R16: =if(Q16+P16+N16=0,"-",Q16+P16+N16) -> 6 | S16: =if(iferror((N16-Q16)/R16,0)=0,"-",round((N16-Q16)/R16,2)) -> -0.33 | T16: =SUMIFS('3월 단양 개인별 STAT'!T:T, '3월 단양 개인별 STAT'!$D:$D, $D16, '3월 단양 개인별 STAT'!$E:$E, $E16) + SUMIFS('4월 삼척 개인별 STAT'!T:T, '4월 삼척 개인별 STAT'!$D:$D, $D16, '4월 삼척 개인별 STAT'!$E:$E, $E16) -> 0 | U16: =SUMIFS('3월 단양 개인별 STAT'!U:U, '3월 단양 개인별 STAT'!$D:$D, $D16, '3월 단양 개인별 STAT'!$E:$E, $E16) + SUMIFS('4월 삼척 개인별 STAT'!U:U, '4월 삼척 개인별 STAT'!$D:$D, $D16, '4월 삼척 개인별 STAT'!$E:$E, $E16) -> 0 | V16: =SUMIFS('3월 단양 개인별 STAT'!V:V, '3월 단양 개인별 STAT'!$D:$D, $D16, '3월 단양 개인별 STAT'!$E:$E, $E16) + SUMIFS('4월 삼척 개인별 STAT'!V:V, '4월 삼척 개인별 STAT'!$D:$D, $D16, '4월 삼척 개인별 STAT'!$E:$E, $E16) -> 0 | W16: =SUMIFS('3월 단양 개인별 STAT'!W:W, '3월 단양 개인별 STAT'!$D:$D, $D16, '3월 단양 개인별 STAT'!$E:$E, $E16) + SUMIFS('4월 삼척 개인별 STAT'!W:W, '4월 삼척 개인별 STAT'!$D:$D, $D16, '4월 삼척 개인별 STAT'!$E:$E, $E16) -> 6 | X16: =SUMIFS('3월 단양 개인별 STAT'!X:X, '3월 단양 개인별 STAT'!$D:$D, $D16, '3월 단양 개인별 STAT'!$E:$E, $E16) + SUMIFS('4월 삼척 개인별 STAT'!X:X, '4월 삼척 개인별 STAT'!$D:$D, $D16, '4월 삼척 개인별 STAT'!$E:$E, $E16) -> 0 | Y16: =SUMIFS('3월 단양 개인별 STAT'!Y:Y, '3월 단양 개인별 STAT'!$D:$D, $D16, '3월 단양 개인별 STAT'!$E:$E, $E16) + SUMIFS('4월 삼척 개인별 STAT'!Y:Y, '4월 삼척 개인별 STAT'!$D:$D, $D16, '4월 삼척 개인별 STAT'!$E:$E, $E16) -> 2 | Z16: =IF(Y16+X16+W16=0,"-",Y16+X16+W16) -> 8 | AA16: =SUMIFS('3월 단양 개인별 STAT'!AA:AA, '3월 단양 개인별 STAT'!$D:$D, $D16, '3월 단양 개인별 STAT'!$E:$E, $E16) + SUMIFS('4월 삼척 개인별 STAT'!AA:AA, '4월 삼척 개인별 STAT'!$D:$D, $D16, '4월 삼척 개인별 STAT'!$E:$E, $E16) -> 0 | AB16: =if((T16+X16+N16)=0, "-",T16+X16+N16) -> - | AC16: =N16+T16+X16+(V16*0.75) -> 0 | AD16: =IF(AE16+AF16=0,"-",AE16+AF16) -> - | AE16: =SUMIFS('3월 단양 개인별 STAT'!AE:AE, '3월 단양 개인별 STAT'!$D:$D, $D16, '3월 단양 개인별 STAT'!$E:$E, $E16) + SUMIFS('4월 삼척 개인별 STAT'!AE:AE, '4월 삼척 개인별 STAT'!$D:$D, $D16, '4월 삼척 개인별 STAT'!$E:$E, $E16) -> 0 | AF16: =SUMIFS('3월 단양 개인별 STAT'!AF:AF, '3월 단양 개인별 STAT'!$D:$D, $D16, '3월 단양 개인별 STAT'!$E:$E, $E16) + SUMIFS('4월 삼척 개인별 STAT'!AF:AF, '4월 삼척 개인별 STAT'!$D:$D, $D16, '4월 삼척 개인별 STAT'!$E:$E, $E16) -> 0 | AG16: =iferror((AE16/AD16)*100,"-") -> - | AH16: =SUMIFS('3월 단양 개인별 STAT'!AH:AH, '3월 단양 개인별 STAT'!$D:$D, $D16, '3월 단양 개인별 STAT'!$E:$E, $E16) + SUMIFS('4월 삼척 개인별 STAT'!AH:AH, '4월 삼척 개인별 STAT'!$D:$D, $D16, '4월 삼척 개인별 STAT'!$E:$E, $E16) -> 6 | AI16: =IFERROR(IF(MOD(AH16/M16, 1)=0, TEXT(AH16/M16, "0"), TEXT(AH16/M16, "0.00")), "-") -> 1.50 | AL16: =iferror(N16/$M16,"-") -> 0 | AM16: =iferror(R16/$M16,"-") -> 1.5 | AN16: =iferror(N16/R16,"-") -> 0 | AO16: =iferror(T16/$M16,"-") -> 0 | AP16: =iferror(X16/$M16,"-") -> 0 | AQ16: =iferror(AB16/$M16,"-") -> - | AR16: =iferror(AC16/$M16,"-") -> 0 | AS16: =iferror(AF16/M16,"-") -> 0 | AT16: =AI16 -> 1.50
B17: 14 | C17: =if(D17=D16,C16+1,1) -> 14 | D17: 선명여고 | E17: 문은영 | F17: 1 | G17: Li | H17: - | I17: 162 | J17: 61 | K17: 19 | L17: =SUMIFS('3월 단양 개인별 STAT'!L:L, '3월 단양 개인별 STAT'!$D:$D, $D17, '3월 단양 개인별 STAT'!$E:$E, $E17) + SUMIFS('4월 삼척 개인별 STAT'!L:L, '4월 삼척 개인별 STAT'!$D:$D, $D17, '4월 삼척 개인별 STAT'!$E:$E, $E17) -> 1 | M17: =SUMIFS('3월 단양 개인별 STAT'!M:M, '3월 단양 개인별 STAT'!$D:$D, $D17, '3월 단양 개인별 STAT'!$E:$E, $E17) + SUMIFS('4월 삼척 개인별 STAT'!M:M, '4월 삼척 개인별 STAT'!$D:$D, $D17, '4월 삼척 개인별 STAT'!$E:$E, $E17) -> 1 | N17: =SUMIFS('3월 단양 개인별 STAT'!N:N, '3월 단양 개인별 STAT'!$D:$D, $D17, '3월 단양 개인별 STAT'!$E:$E, $E17) + SUMIFS('4월 삼척 개인별 STAT'!N:N, '4월 삼척 개인별 STAT'!$D:$D, $D17, '4월 삼척 개인별 STAT'!$E:$E, $E17) -> 0 | O17: =SUMIFS('3월 단양 개인별 STAT'!O:O, '3월 단양 개인별 STAT'!$D:$D, $D17, '3월 단양 개인별 STAT'!$E:$E, $E17) + SUMIFS('4월 삼척 개인별 STAT'!O:O, '4월 삼척 개인별 STAT'!$D:$D, $D17, '4월 삼척 개인별 STAT'!$E:$E, $E17) -> 1 | P17: =SUMIFS('3월 단양 개인별 STAT'!P:P, '3월 단양 개인별 STAT'!$D:$D, $D17, '3월 단양 개인별 STAT'!$E:$E, $E17) + SUMIFS('4월 삼척 개인별 STAT'!P:P, '4월 삼척 개인별 STAT'!$D:$D, $D17, '4월 삼척 개인별 STAT'!$E:$E, $E17) -> 0 | Q17: =SUMIFS('3월 단양 개인별 STAT'!Q:Q, '3월 단양 개인별 STAT'!$D:$D, $D17, '3월 단양 개인별 STAT'!$E:$E, $E17) + SUMIFS('4월 삼척 개인별 STAT'!Q:Q, '4월 삼척 개인별 STAT'!$D:$D, $D17, '4월 삼척 개인별 STAT'!$E:$E, $E17) -> 0 | R17: =if(Q17+P17+N17=0,"-",Q17+P17+N17) -> - | S17: =if(iferror((N17-Q17)/R17,0)=0,"-",round((N17-Q17)/R17,2)) -> - | T17: =SUMIFS('3월 단양 개인별 STAT'!T:T, '3월 단양 개인별 STAT'!$D:$D, $D17, '3월 단양 개인별 STAT'!$E:$E, $E17) + SUMIFS('4월 삼척 개인별 STAT'!T:T, '4월 삼척 개인별 STAT'!$D:$D, $D17, '4월 삼척 개인별 STAT'!$E:$E, $E17) -> 0 | U17: =SUMIFS('3월 단양 개인별 STAT'!U:U, '3월 단양 개인별 STAT'!$D:$D, $D17, '3월 단양 개인별 STAT'!$E:$E, $E17) + SUMIFS('4월 삼척 개인별 STAT'!U:U, '4월 삼척 개인별 STAT'!$D:$D, $D17, '4월 삼척 개인별 STAT'!$E:$E, $E17) -> 0 | V17: =SUMIFS('3월 단양 개인별 STAT'!V:V, '3월 단양 개인별 STAT'!$D:$D, $D17, '3월 단양 개인별 STAT'!$E:$E, $E17) + SUMIFS('4월 삼척 개인별 STAT'!V:V, '4월 삼척 개인별 STAT'!$D:$D, $D17, '4월 삼척 개인별 STAT'!$E:$E, $E17) -> 0 | W17: =SUMIFS('3월 단양 개인별 STAT'!W:W, '3월 단양 개인별 STAT'!$D:$D, $D17, '3월 단양 개인별 STAT'!$E:$E, $E17) + SUMIFS('4월 삼척 개인별 STAT'!W:W, '4월 삼척 개인별 STAT'!$D:$D, $D17, '4월 삼척 개인별 STAT'!$E:$E, $E17) -> 0 | X17: =SUMIFS('3월 단양 개인별 STAT'!X:X, '3월 단양 개인별 STAT'!$D:$D, $D17, '3월 단양 개인별 STAT'!$E:$E, $E17) + SUMIFS('4월 삼척 개인별 STAT'!X:X, '4월 삼척 개인별 STAT'!$D:$D, $D17, '4월 삼척 개인별 STAT'!$E:$E, $E17) -> 0 | Y17: =SUMIFS('3월 단양 개인별 STAT'!Y:Y, '3월 단양 개인별 STAT'!$D:$D, $D17, '3월 단양 개인별 STAT'!$E:$E, $E17) + SUMIFS('4월 삼척 개인별 STAT'!Y:Y, '4월 삼척 개인별 STAT'!$D:$D, $D17, '4월 삼척 개인별 STAT'!$E:$E, $E17) -> 0 | Z17: =IF(Y17+X17+W17=0,"-",Y17+X17+W17) -> - | AA17: =SUMIFS('3월 단양 개인별 STAT'!AA:AA, '3월 단양 개인별 STAT'!$D:$D, $D17, '3월 단양 개인별 STAT'!$E:$E, $E17) + SUMIFS('4월 삼척 개인별 STAT'!AA:AA, '4월 삼척 개인별 STAT'!$D:$D, $D17, '4월 삼척 개인별 STAT'!$E:$E, $E17) -> 0 | AB17: =if((T17+X17+N17)=0, "-",T17+X17+N17) -> - | AC17: =N17+T17+X17+(V17*0.75) -> 0 | AD17: =IF(AE17+AF17=0,"-",AE17+AF17) -> 4 | AE17: =SUMIFS('3월 단양 개인별 STAT'!AE:AE, '3월 단양 개인별 STAT'!$D:$D, $D17, '3월 단양 개인별 STAT'!$E:$E, $E17) + SUMIFS('4월 삼척 개인별 STAT'!AE:AE, '4월 삼척 개인별 STAT'!$D:$D, $D17, '4월 삼척 개인별 STAT'!$E:$E, $E17) -> 3 | AF17: =SUMIFS('3월 단양 개인별 STAT'!AF:AF, '3월 단양 개인별 STAT'!$D:$D, $D17, '3월 단양 개인별 STAT'!$E:$E, $E17) + SUMIFS('4월 삼척 개인별 STAT'!AF:AF, '4월 삼척 개인별 STAT'!$D:$D, $D17, '4월 삼척 개인별 STAT'!$E:$E, $E17) -> 1 | AG17: =iferror((AE17/AD17)*100,"-") -> 75 | AH17: =SUMIFS('3월 단양 개인별 STAT'!AH:AH, '3월 단양 개인별 STAT'!$D:$D, $D17, '3월 단양 개인별 STAT'!$E:$E, $E17) + SUMIFS('4월 삼척 개인별 STAT'!AH:AH, '4월 삼척 개인별 STAT'!$D:$D, $D17, '4월 삼척 개인별 STAT'!$E:$E, $E17) -> 0 | AI17: =IFERROR(IF(MOD(AH17/M17, 1)=0, TEXT(AH17/M17, "0"), TEXT(AH17/M17, "0.00")), "-") -> 0 | AL17: =iferror(N17/$M17,"-") -> 0 | AM17: =iferror(R17/$M17,"-") -> - | AN17: =iferror(N17/R17,"-") -> - | AO17: =iferror(T17/$M17,"-") -> 0 | AP17: =iferror(X17/$M17,"-") -> 0 | AQ17: =iferror(AB17/$M17,"-") -> - | AR17: =iferror(AC17/$M17,"-") -> 0 | AS17: =iferror(AF17/M17,"-") -> 1 | AT17: =AI17 -> 0
